Workbook

Sheet Form Responses 1
A1: Timestamp | B1: Team Name | C1: SR / Ticket number | D1: ONT Replaced | E1: Replaced ONT | F1: New ONT Serial No | G1: OLD ONT Serial No | H1: Patch Chord | I1: Fiber Termination Box (FTB) | J1: Pigtail | K1: Fiber Protection Sleeves | L1: Cable 2F, SM, Fully Filled, (Internal cable) | M1: Fiber Termination Box, 2F, SC, Outdoor | N1: Quick SC/UPC Connector Blue | O1: Cable4F, SM, Outdoor (External Cable) | P1: DRAWROPE | Q1: FIBER CAPPING | R1: FIBER CONNECTOR BEND | S1: CLAMP, D/W NO.10A,(NYLON COATED STEEL WIRE | T1: CABLE 2F,GPON AERIAL DROP,BTC/1023/FIBER | U1: BRACKET | V1: Adaptor | W1: Comments and/or questions | X1: ONT Power Adaptor | Y1: Email Address | Z1: Invisible Optical cable (1000525) | AA1: FTTR patch Chord | AB1: ATB 2121 SC/APC (1000524) | AC1: FTTR Splitter | AD1: Quick SC/APC Connector Green | AE1: Column 29
A3: 46069.744 | B3: Zubair | C3: 20067866 | D3: Yes | E3: FTTR Master ONT | F3: 48575443FBA858B6 | G3: 48575443ABB2D7A1 | H3: 1 | Y3: zubairshoukat23@gmail.com
A4: 46069.744 | B4: Zubair | C4: 20067880 | D4: NO | N4: 1 | Y4: zubairshoukat23@gmail.com
A5: 46069.745 | B5: Zubair | C5: 20067799 | D5: NO | H5: 1 | Y5: zubairshoukat23@gmail.com
A6: 46069.745 | B6: Zubair | C6: 20067818 | D6: NO | N6: 1 | Y6: zubairshoukat23@gmail.com
A7: 46069.746 | B7: Zubair | C7: 20067819 | D7: NO | K7: 1 | Y7: zubairshoukat23@gmail.com
A8: 46069.85 | B8: Zubair | C8: 20067888 | D8: NO | H8: 1 | I8: 1 | J8: 1 | Y8: zubairshoukat23@gmail.com
A9: 46070.412 | B9: Nasir | C9: 20067572 | D9: Yes | E9: WiFi-6 | F9: 485754436F7604AF | G9: 485754437AE47AA7 | Y9: funkedunya9@gmail.com
A10: 46070.431 | B10: Mohsin | C10: 20067910 | D10: Yes | E10: H-5 | F10: 48575443BB28F8B3 | G10: 4857544308C26CB4 | H10: 0 | I10: 0 | J10: 0 | K10: 0 | L10: 0 | M10: 0 | N10: 0 | O10: 0 | P10: 0 | Q10: 0 | R10: 0 | S10: 0 | T10: 0 | U10: 0 | V10: 0 | X10: 1 | Y10: alikhan22dec@gmail.com | Z10: 0 | AA10: 0 | AB10: 0 | AC10: 0 | AD10: 0
A11: 46070.433 | B11: Mohsin | C11: 20067887 | D11: Yes | E11: H-5 | F11: 48575443BB24C6B3 | G11: 4857544308C1ECB4 | H11: 0 | I11: 0 | J11: 0 | K11: 0 | L11: 0 | M11: 0 | N11: 0 | O11: 0 | P11: 0 | Q11: 0 | R11: 0 | S11: 0 | T11: 0 | U11: 0 | V11: 0 | X11: 1 | Y11: alikhan22dec@gmail.com | Z11: 0 | AA11: 0 | AB11: 0 | AC11: 0 | AD11: 0
A12: 46070.433 | B12: Mohsin | C12: 20067876 | D12: NO | H12: 0 | I12: 0 | J12: 0 | K12: 1 | L12: 0 | M12: 1 | N12: 0 | O12: 0 | P12: 0 | Q12: 0 | R12: 0 | S12: 0 | T12: 0 | U12: 0 | V12: 0 | W12: 0 | X12: 0 | Y12: alikhan22dec@gmail.com | Z12: 0 | AA12: 0 | AB12: 0 | AC12: 0 | AD12: 0
A13: 46070.435 | B13: Mohsin | C13: 20067825 | D13: NO | H13: 0 | I13: 0 | J13: 0 | K13: 0 | L13: 0 | M13: 0 | N13: 1 | O13: 0 | P13: 0 | Q13: 0 | R13: 0 | S13: 0 | T13: 0 | U13: 0 | V13: 0 | X13: 0 | Y13: alikhan22dec@gmail.com | Z13: 0 | AA13: 0 | AB13: 0 | AC13: 0 | AD13: 0
A14: 46070.52 | B14: Nasir | C14: 20067811 | D14: NO | H14: 1 | Y14: funkedunya9@gmail.com
A15: 46070.522 | B15: Nasir | C15: 20067858 | D15: NO | K15: 2 | O15: 75 | Y15: funkedunya9@gmail.com
A16: 46070.523 | B16: Nasir | C16: 20067872 | D16: NO | H16: 1 | Y16: funkedunya9@gmail.com
A17: 46070.524 | B17: Nasir | C17: 20067814 | D17: NO | J17: 1 | K17: 2 | N17: 1 | T17: 60m | Y17: funkedunya9@gmail.com
A18: 46070.525 | B18: Nasir | C18: 20067904 | D18: NO | J18: 1 | K18: 1 | Y18: funkedunya9@gmail.com
A19: 46070.526 | B19: Nasir | C19: 20067924 | D19: NO | J19: 1 | K19: 1 | L19: 55m | Y19: funkedunya9@gmail.com
A20: 46070.743 | B20: Nasir | C20: 20067846 | D20: NO | J20: 1 | K20: 1 | Y20: funkedunya9@gmail.com
A21: 46070.744 | B21: Nasir | C21: 20067995 | D21: NO | J21: 1 | K21: 1 | Y21: funkedunya9@gmail.com
A22: 46070.764 | B22: Nasir | C22: 20067994 | D22: Yes | E22: WiFi-6 | F22: 4857544344E8B0B3 | G22: 48575443C4BB983A | Y22: funkedunya9@gmail.com
A23: 46070.833 | B23: Nasir | C23: 20068009 | D23: NO | H23: 1 | Y23: funkedunya9@gmail.com
A24: 46071.43 | B24: Zubair | C24: 20067983 | D24: Yes | E24: FTTR Master ONT | F24: 48575443FBAB0CB6 | G24: 4857544305C4659E | Y24: zubairshoukat23@gmail.com
A25: 46071.431 | B25: Zubair | C25: 20067991 | D25: NO | X25: 1 | Y25: zubairshoukat23@gmail.com
A26: 46071.431 | B26: Zubair | C26: 20067979 | D26: NO | H26: 1 | Y26: zubairshoukat23@gmail.com
A27: 46071.432 | B27: Zubair | C27: 20067928 | D27: NO | X27: 1 | Y27: zubairshoukat23@gmail.com
A28: 46071.432 | B28: Zubair | C28: 20067943 | D28: NO | J28: 1 | K28: 1 | L28: 25 | N28: 1 | Y28: zubairshoukat23@gmail.com
A29: 46071.433 | B29: Zubair | C29: 20067942 | D29: NO | J29: 1 | K29: 1 | Y29: zubairshoukat23@gmail.com
A30: 46071.433 | B30: Zubair | C30: 20067931 | D30: NO | K30: 1 | Y30: zubairshoukat23@gmail.com
A31: 46071.811 | B31: Zubair | C31: 20068086 | D31: NO | N31: 1 | Y31: zubairshoukat23@gmail.com
A32: 46071.811 | B32: Zubair | C32: 20068087 | D32: NO | K32: 1 | Y32: zubairshoukat23@gmail.com
A33: 46071.812 | B33: Zubair | C33: 20068068 | D33: NO | V33: 1 | Y33: zubairshoukat23@gmail.com
A34: 46071.813 | B34: Zubair | C34: 20068072 | D34: Yes | E34: FTTR Master ONT | F34: 48575443FBA7D5B6 | G34: 4857544389F6C3A3 | Y34: zubairshoukat23@gmail.com
A35: 46071.814 | B35: Zubair | C35: 20068071 | D35: Yes | E35: FTTR Master ONT | F35: 48575443FBACC1B6 | G35: 4857544328FB32AF | Y35: zubairshoukat23@gmail.com
A36: 46071.814 | B36: Zubair | C36: 20068032 | D36: NO | K36: 1 | Y36: zubairshoukat23@gmail.com
A37: 46071.814 | B37: Zubair | C37: 20068027 | D37: NO | I37: 1 | J37: 1 | K37: 1 | Y37: zubairshoukat23@gmail.com
A38: 46071.815 | B38: Zubair | C38: 20068016 | D38: NO | K38: 1 | Y38: zubairshoukat23@gmail.com
A39: 46071.832 | B39: Bilal Bacha | C39: 20068057 | D39: Yes | E39: 2G | F39: SN:48575443400E3DB1 | G39: sn:48575443401168B1 | Y39: funkedunya9@gmail.com
A40: 46071.833 | B40: Bilal Bacha | C40: 20067846 | D40: Yes | E40: FTTR Master ONT | F40: sn:48575443FBA7CDB6 | G40: sn:485754432900D5AF | Y40: funkedunya9@gmail.com
A41: 46071.833 | B41: Bilal Bacha | C41: 20068089 | D41: NO | H41: 1 | Y41: funkedunya9@gmail.com
...

Sheet Sheet3

Sheet Sheet1
A4: Item No
A5: Unit
A6: {='Form Responses 1'!A:Z} -> Timestamp | B6: Team Name | C6: SR / Ticket number | D6: ONT Replaced | E6: Replaced ONT | F6: New ONT Serial No | G6: OLD ONT Serial No | H6: Patch Chord | I6: Fiber Termination Box (FTB) | J6: Pigtail | K6: Fiber Protection Sleeves | L6: Cable 2F, SM, Fully Filled, (Internal cable) | M6: Fiber Termination Box, 2F, SC, Outdoor | N6: Quick SC/UPC Connector Blue | O6: Cable4F, SM, Outdoor (External Cable) | P6: DRAWROPE | Q6: FIBER CAPPING | R6: FIBER CONNECTOR BEND | S6: CLAMP, D/W NO.10A,(NYLON COATED STEEL WIRE | T6: CABLE 2F,GPON AERIAL DROP,BTC/1023/FIBER | U6: BRACKET | V6: Adaptor | W6: Comments and/or questions | X6: ONT Power Adaptor | Y6: Email Address | Z6: Invisible Optical cable (1000525)
A8: 46069.744 | B8: Zubair | C8: 20067866 | D8: Yes | E8: FTTR Master ONT | F8: 48575443FBA858B6 | G8: 48575443ABB2D7A1 | H8: 1 | Y8: zubairshoukat23@gmail.com
A9: 46069.744 | B9: Zubair | C9: 20067880 | D9: NO | N9: 1 | Y9: zubairshoukat23@gmail.com
A10: 46069.745 | B10: Zubair | C10: 20067799 | D10: NO | H10: 1 | Y10: zubairshoukat23@gmail.com
A11: 46069.745 | B11: Zubair | C11: 20067818 | D11: NO | N11: 1 | Y11: zubairshoukat23@gmail.com
A12: 46069.746 | B12: Zubair | C12: 20067819 | D12: NO | K12: 1 | Y12: zubairshoukat23@gmail.com
A13: 46069.85 | B13: Zubair | C13: 20067888 | D13: NO | H13: 1 | I13: 1 | J13: 1 | Y13: zubairshoukat23@gmail.com
A14: 46070.412 | B14: Nasir | C14: 20067572 | D14: Yes | E14: WiFi-6 | F14: 485754436F7604AF | G14: 485754437AE47AA7 | Y14: funkedunya9@gmail.com
A15: 46070.431 | B15: Mohsin | C15: 20067910 | D15: Yes | E15: H-5 | F15: 48575443BB28F8B3 | G15: 4857544308C26CB4 | H15: 0 | I15: 0 | J15: 0 | K15: 0 | L15: 0 | M15: 0 | N15: 0 | O15: 0 | P15: 0 | Q15: 0 | R15: 0 | S15: 0 | T15: 0 | U15: 0 | V15: 0 | X15: 1 | Y15: alikhan22dec@gmail.com | Z15: 0
A16: 46070.433 | B16: Mohsin | C16: 20067887 | D16: Yes | E16: H-5 | F16: 48575443BB24C6B3 | G16: 4857544308C1ECB4 | H16: 0 | I16: 0 | J16: 0 | K16: 0 | L16: 0 | M16: 0 | N16: 0 | O16: 0 | P16: 0 | Q16: 0 | R16: 0 | S16: 0 | T16: 0 | U16: 0 | V16: 0 | X16: 1 | Y16: alikhan22dec@gmail.com | Z16: 0
A17: 46070.433 | B17: Mohsin | C17: 20067876 | D17: NO | H17: 0 | I17: 0 | J17: 0 | K17: 1 | L17: 0 | M17: 1 | N17: 0 | O17: 0 | P17: 0 | Q17: 0 | R17: 0 | S17: 0 | T17: 0 | U17: 0 | V17: 0 | W17: 0 | X17: 0 | Y17: alikhan22dec@gmail.com | Z17: 0
A18: 46070.435 | B18: Mohsin | C18: 20067825 | D18: NO | H18: 0 | I18: 0 | J18: 0 | K18: 0 | L18: 0 | M18: 0 | N18: 1 | O18: 0 | P18: 0 | Q18: 0 | R18: 0 | S18: 0 | T18: 0 | U18: 0 | V18: 0 | X18: 0 | Y18: alikhan22dec@gmail.com | Z18: 0
A19: 46070.52 | B19: Nasir | C19: 20067811 | D19: NO | H19: 1 | Y19: funkedunya9@gmail.com
A20: 46070.522 | B20: Nasir | C20: 20067858 | D20: NO | K20: 2 | O20: 75 | Y20: funkedunya9@gmail.com
A21: 46070.523 | B21: Nasir | C21: 20067872 | D21: NO | H21: 1 | Y21: funkedunya9@gmail.com
A22: 46070.524 | B22: Nasir | C22: 20067814 | D22: NO | J22: 1 | K22: 2 | N22: 1 | T22: 60m | Y22: funkedunya9@gmail.com
A23: 46070.525 | B23: Nasir | C23: 20067904 | D23: NO | J23: 1 | K23: 1 | Y23: funkedunya9@gmail.com
A24: 46070.526 | B24: Nasir | C24: 20067924 | D24: NO | J24: 1 | K24: 1 | L24: 55m | Y24: funkedunya9@gmail.com
A25: 46070.743 | B25: Nasir | C25: 20067846 | D25: NO | J25: 1 | K25: 1 | Y25: funkedunya9@gmail.com
A26: 46070.744 | B26: Nasir | C26: 20067995 | D26: NO | J26: 1 | K26: 1 | Y26: funkedunya9@gmail.com
A27: 46070.764 | B27: Nasir | C27: 20067994 | D27: Yes | E27: WiFi-6 | F27: 4857544344E8B0B3 | G27: 48575443C4BB983A | Y27: funkedunya9@gmail.com
A28: 46070.833 | B28: Nasir | C28: 20068009 | D28: NO | H28: 1 | Y28: funkedunya9@gmail.com
A29: 46071.43 | B29: Zubair | C29: 20067983 | D29: Yes | E29: FTTR Master ONT | F29: 48575443FBAB0CB6 | G29: 4857544305C4659E | Y29: zubairshoukat23@gmail.com
A30: 46071.431 | B30: Zubair | C30: 20067991 | D30: NO | X30: 1 | Y30: zubairshoukat23@gmail.com
A31: 46071.431 | B31: Zubair | C31: 20067979 | D31: NO | H31: 1 | Y31: zubairshoukat23@gmail.com
A32: 46071.432 | B32: Zubair | C32: 20067928 | D32: NO | X32: 1 | Y32: zubairshoukat23@gmail.com
A33: 46071.432 | B33: Zubair | C33: 20067943 | D33: NO | J33: 1 | K33: 1 | L33: 25 | N33: 1 | Y33: zubairshoukat23@gmail.com
A34: 46071.433 | B34: Zubair | C34: 20067942 | D34: NO | J34: 1 | K34: 1 | Y34: zubairshoukat23@gmail.com
A35: 46071.433 | B35: Zubair | C35: 20067931 | D35: NO | K35: 1 | Y35: zubairshoukat23@gmail.com
A36: 46071.811 | B36: Zubair | C36: 20068086 | D36: NO | N36: 1 | Y36: zubairshoukat23@gmail.com
A37: 46071.811 | B37: Zubair | C37: 20068087 | D37: NO | K37: 1 | Y37: zubairshoukat23@gmail.com
A38: 46071.812 | B38: Zubair | C38: 20068068 | D38: NO | V38: 1 | Y38: zubairshoukat23@gmail.com
A39: 46071.813 | B39: Zubair | C39: 20068072 | D39: Yes | E39: FTTR Master ONT | F39: 48575443FBA7D5B6 | G39: 4857544389F6C3A3 | Y39: zubairshoukat23@gmail.com
A40: 46071.814 | B40: Zubair | C40: 20068071 | D40: Yes | E40: FTTR Master ONT | F40: 48575443FBACC1B6 | G40: 4857544328FB32AF | Y40: zubairshoukat23@gmail.com
A41: 46071.814 | B41: Zubair | C41: 20068032 | D41: NO | K41: 1 | Y41: zubairshoukat23@gmail.com
A42: 46071.814 | B42: Zubair | C42: 20068027 | D42: NO | I42: 1 | J42: 1 | K42: 1 | Y42: zubairshoukat23@gmail.com
A43: 46071.815 | B43: Zubair | C43: 20068016 | D43: NO | K43: 1 | Y43: zubairshoukat23@gmail.com
A44: 46071.832 | B44: Bilal Bacha | C44: 20068057 | D44: Yes | E44: 2G | F44: SN:48575443400E3DB1 | G44: sn:48575443401168B1 | Y44: funkedunya9@gmail.com
...

Sheet Tech Sheet Replica
F1: GPON Last Mile | S1: GPON Assurance | AJ1: Copper Assurace | AW1: ONT Details
F2: Underground Materials | O2: Overhead Material | S2: In Building Materials | AD2: Internal Wiring Materials | AF2: Last Point Materials | AJ2: Copper Materials | AY2: Remarks
A3: Iteam No | F3: 1000048 | G3: 1000079 | H3: 1000084 | I3: 1000085 | J3: 1000105 | K3: 1000087 | L3: 10000466 | M3: None | N3: 1000086 | O3: 1000021 | P3: 1000067 | Q3: 1000187 | R3: 1000040 | S3: 1000087 | T3: 1000187 | U3: 1000086 | V3: 1000185 | W3: 1000104 | X3: 1000041 | Y3: 1000048 | AA3: 1000001 | AB3: 1000092 | AC3: 1000098 | AD3: None | AE3: None | AF3: 10000471 | AH3: 1000148 | AI3: 1000172 | AJ3: 1000022 | AK3: 1000042 | AL3: 1000541 | AM3: 1000553 | AN3: 1000067 | AO3: 1000021 | AP3: 1001965 | AQ3: 1001968 | AR3: 1004110 | AS3: 1004400 | AT3: 1004425 | AU3: 1004428 | AV3: 1000214
A4: Unit | F4: Meter | G4: Meter | H4: piece | I4: piece | J4: piece | K4: piece | L4: piece | M4: piece | N4: piece | O4: piece | P4: piece | Q4: piece | R4: piece | S4: piece | T4: piece | U4: piece | V4: Kit | W4: piece | X4: Meter | Y4: Meter | Z4: piece | AA4: piece | AB4: piece | AC4: piece | AD4: Meter | AE4: Meter | AF4: piece | AG4: piece | AH4: piece | AI4: piece | AJ4: Meter | AK4: Meter | AL4: Meter | AM4: Meter | AN4: piece | AO4: piece | AP4: EA | AQ4: EA | AR4: EA | AS4: EA | AT4: EA | AU4: EA | AV4: EA
A5: Date | B5: Fault Number | C5: Fault Type | D5: Close Type | E5: Fault Clearnes Code | F5: Cable4F,SM,Outdoor(4F/Tube),GPON | G5: DRAWROPE,NO.1 500M/ 0.6 MM, BT 071830 CW | H5: FIBER CAPPING | I5: FIBER CONNECTOR BEND | J5: Fiber Termination Box, 2F, SC,In/Outdoor | K5: Fiber Mechanical Splice, 1F, SM/MM | L5: Bare Fiber Sleeves, Protection Sleeve-Single 60mm | M5: Heat Shrink for External Cables | N5: FIBER HOUSE TERMINATION BOX,1F,SM,INDO | O5: BRACKET,NO.22,011114 | P5: CLAMP,D/W NO.10A,(NYLON COATED STEEL WIR | Q5: Quick SC/UPC Connector Blue for GPON | R5: CABLE 2F,GPON AERIAL DROP,BTC/1023/FIBER | S5: Fiber Mechanical Splice, 1F, SM/MM2 | T5: Quick SC/UPC Connector Blue for GPON2 | U5: FIBER HOUSE TERMINATION BOX,1F,SM,INDO2 | V5: QUICK SC CONNECTOR KIT FOR SM FIBRE | W5: BNET-PIGTAIL-SM-SC/UPC-UNIVERSAL | X5: Cable2F,SM,Fully Filled,BTC/1021/Fibre | Y5: Cable4F,SM,Outdoor(4F/Tube),GPON2 | Z5: Quick SC/UPC Connector blue for GPON | AA5: ADAPTER, SIMPLEX SC, BLUE PLASTIC | AB5: FIBER PATCH CORD,SC/SCSM, DUPLEX, 4M | AC5: FIBER PATCH CORD,SC/LC SM, DUPLEX,4M | AD5: 20mm Piping | AE5: 16mm Trunking | AF5: ONT - Bnet WiFi 6 | AG5: ONT - Bnet H5 | AH5: ONT - ETISALCOM | AI5: Patch cord | AJ5: CABLE DROPWIRE NO.10, CW1411 | AK5: CABLE,2PR/0.5MM,TWISTED TCW PVC INSUL.WH | AL5: CABLE,2 PR/0.5MM ,LEADING_IN SP1068 | AM5: JUMPER,2W/0.5,7000SERIES,(BLU/YL) 400M | AN5: CLAMP,D/W NO.10A,(NYLON COATED STEEL WIR2 | AO5: BRACKET,NO.22,0111142 | AP5: PLUG 4-WIRE 6-POS AMERICAN TYPE WE4 LINE | AQ5: B.S PLUG 431A | AR5: CONNECTOR,3M UR2 RED(IN CARTRIDGES) | AS5: BOX PLASTIC PVC,3X3"(FOR LINE JACK UNIT) | AT5: JACK LINE,UNIT 3/4A,MASTER (WITH LOGO) | AU5: JACK,4/4A,MASTER,(WITH BATELCO LOGO) | AV5: TP-LINK ARCHER VR600 AC1600 | AW5: ONT S/N | AX5: ONT Reservation No. 4910000924 | AY5: Add Noted
A6: ='Form Responses 1'!A3 -> 46069.744 | B6: ='Form Responses 1'!C3 -> 20067866 | F6: ='Form Responses 1'!O3 | G6: ='Form Responses 1'!P3 | H6: ='Form Responses 1'!Q3 | I6: ='Form Responses 1'!R3 | J6: ='Form Responses 1'!M3 | L6: ='Form Responses 1'!K3 | N6: ='Form Responses 1'!I3 | O6: ='Form Responses 1'!U3 | P6: ='Form Responses 1'!S3 | Q6: ='Form Responses 1'!N3 | R6: ='Form Responses 1'!T3 | U6: ='Form Responses 1'!I3 | W6: ='Form Responses 1'!J3 | X6: ='Form Responses 1'!L3 | Z6: ='Form Responses 1'!N3 | AA6: ='Form Responses 1'!V3 | AF6: ='Form Responses 1'!E3 -> FTTR Master ONT | AI6: ='Form Responses 1'!H3 -> 1 | AW6: ='Form Responses 1'!F3 -> 48575443FBA858B6
A7: ='Form Responses 1'!A4 -> 46069.744 | B7: ='Form Responses 1'!C4 -> 20067880 | F7: ='Form Responses 1'!O4 | G7: ='Form Responses 1'!P4 | H7: ='Form Responses 1'!Q4 | I7: ='Form Responses 1'!R4 | J7: ='Form Responses 1'!M4 | L7: ='Form Responses 1'!K4 | N7: ='Form Responses 1'!I4 | O7: ='Form Responses 1'!U4 | P7: ='Form Responses 1'!S4 | Q7: ='Form Responses 1'!N4 -> 1 | R7: ='Form Responses 1'!T4 | U7: ='Form Responses 1'!I4 | W7: ='Form Responses 1'!J4 | X7: ='Form Responses 1'!L4 | Z7: ='Form Responses 1'!N4 -> 1 | AA7: ='Form Responses 1'!V4 | AF7: ='Form Responses 1'!E4 | AI7: ='Form Responses 1'!H4 | AW7: ='Form Responses 1'!F4
A8: ='Form Responses 1'!A5 -> 46069.745 | B8: ='Form Responses 1'!C5 -> 20067799 | F8: ='Form Responses 1'!O5 | G8: ='Form Responses 1'!P5 | H8: ='Form Responses 1'!Q5 | I8: ='Form Responses 1'!R5 | J8: ='Form Responses 1'!M5 | L8: ='Form Responses 1'!K5 | N8: ='Form Responses 1'!I5 | O8: ='Form Responses 1'!U5 | P8: ='Form Responses 1'!S5 | Q8: ='Form Responses 1'!N5 | R8: ='Form Responses 1'!T5 | U8: ='Form Responses 1'!I5 | W8: ='Form Responses 1'!J5 | X8: ='Form Responses 1'!L5 | Z8: ='Form Responses 1'!N5 | AA8: ='Form Responses 1'!V5 | AF8: ='Form Responses 1'!E5 | AI8: ='Form Responses 1'!H5 -> 1 | AW8: ='Form Responses 1'!F5
A9: ='Form Responses 1'!A6 -> 46069.745 | B9: ='Form Responses 1'!C6 -> 20067818 | F9: ='Form Responses 1'!O6 | G9: ='Form Responses 1'!P6 | H9: ='Form Responses 1'!Q6 | I9: ='Form Responses 1'!R6 | J9: ='Form Responses 1'!M6 | L9: ='Form Responses 1'!K6 | N9: ='Form Responses 1'!I6 | O9: ='Form Responses 1'!U6 | P9: ='Form Responses 1'!S6 | Q9: ='Form Responses 1'!N6 -> 1 | R9: ='Form Responses 1'!T6 | U9: ='Form Responses 1'!I6 | W9: ='Form Responses 1'!J6 | X9: ='Form Responses 1'!L6 | Z9: ='Form Responses 1'!N6 -> 1 | AA9: ='Form Responses 1'!V6 | AF9: ='Form Responses 1'!E6 | AI9: ='Form Responses 1'!H6 | AW9: ='Form Responses 1'!F6
A10: ='Form Responses 1'!A7 -> 46069.746 | B10: ='Form Responses 1'!C7 -> 20067819 | F10: ='Form Responses 1'!O7 | G10: ='Form Responses 1'!P7 | H10: ='Form Responses 1'!Q7 | I10: ='Form Responses 1'!R7 | J10: ='Form Responses 1'!M7 | L10: ='Form Responses 1'!K7 -> 1 | N10: ='Form Responses 1'!I7 | O10: ='Form Responses 1'!U7 | P10: ='Form Responses 1'!S7 | Q10: ='Form Responses 1'!N7 | R10: ='Form Responses 1'!T7 | U10: ='Form Responses 1'!I7 | W10: ='Form Responses 1'!J7 | X10: ='Form Responses 1'!L7 | Z10: ='Form Responses 1'!N7 | AA10: ='Form Responses 1'!V7 | AF10: ='Form Responses 1'!E7 | AI10: ='Form Responses 1'!H7 | AW10: ='Form Responses 1'!F7
A11: ='Form Responses 1'!A8 -> 46069.85 | B11: ='Form Responses 1'!C8 -> 20067888 | F11: ='Form Responses 1'!O8 | G11: ='Form Responses 1'!P8 | H11: ='Form Responses 1'!Q8 | I11: ='Form Responses 1'!R8 | J11: ='Form Responses 1'!M8 | L11: ='Form Responses 1'!K8 | N11: ='Form Responses 1'!I8 -> 1 | O11: ='Form Responses 1'!U8 | P11: ='Form Responses 1'!S8 | Q11: ='Form Responses 1'!N8 | R11: ='Form Responses 1'!T8 | U11: ='Form Responses 1'!I8 -> 1 | W11: ='Form Responses 1'!J8 -> 1 | X11: ='Form Responses 1'!L8 | Z11: ='Form Responses 1'!N8 | AA11: ='Form Responses 1'!V8 | AF11: ='Form Responses 1'!E8 | AI11: ='Form Responses 1'!H8 -> 1 | AW11: ='Form Responses 1'!F8
A12: ='Form Responses 1'!A9 -> 46070.412 | B12: ='Form Responses 1'!C9 -> 20067572 | F12: ='Form Responses 1'!O9 | G12: ='Form Responses 1'!P9 | H12: ='Form Responses 1'!Q9 | I12: ='Form Responses 1'!R9 | J12: ='Form Responses 1'!M9 | L12: ='Form Responses 1'!K9 | N12: ='Form Responses 1'!I9 | O12: ='Form Responses 1'!U9 | P12: ='Form Responses 1'!S9 | Q12: ='Form Responses 1'!N9 | R12: ='Form Responses 1'!T9 | U12: ='Form Responses 1'!I9 | W12: ='Form Responses 1'!J9 | X12: ='Form Responses 1'!L9 | Z12: ='Form Responses 1'!N9 | AA12: ='Form Responses 1'!V9 | AF12: ='Form Responses 1'!E9 -> WiFi-6 | AI12: ='Form Responses 1'!H9 | AW12: ='Form Responses 1'!F9 -> 485754436F7604AF
A13: ='Form Responses 1'!A10 -> 46070.431 | B13: ='Form Responses 1'!C10 -> 20067910 | F13: ='Form Responses 1'!O10 -> 0 | G13: ='Form Responses 1'!P10 -> 0 | H13: ='Form Responses 1'!Q10 -> 0 | I13: ='Form Responses 1'!R10 -> 0 | J13: ='Form Responses 1'!M10 -> 0 | L13: ='Form Responses 1'!K10 -> 0 | N13: ='Form Responses 1'!I10 -> 0 | O13: ='Form Responses 1'!U10 -> 0 | P13: ='Form Responses 1'!S10 -> 0 | Q13: ='Form Responses 1'!N10 -> 0 | R13: ='Form Responses 1'!T10 -> 0 | U13: ='Form Responses 1'!I10 -> 0 | W13: ='Form Responses 1'!J10 -> 0 | X13: ='Form Responses 1'!L10 -> 0 | Z13: ='Form Responses 1'!N10 -> 0 | AA13: ='Form Responses 1'!V10 -> 0 | AF13: ='Form Responses 1'!E10 -> H-5 | AI13: ='Form Responses 1'!H10 -> 0 | AW13: ='Form Responses 1'!F10 -> 48575443BB28F8B3
A14: ='Form Responses 1'!A11 -> 46070.433 | B14: ='Form Responses 1'!C11 -> 20067887 | F14: ='Form Responses 1'!O11 -> 0 | G14: ='Form Responses 1'!P11 -> 0 | H14: ='Form Responses 1'!Q11 -> 0 | I14: ='Form Responses 1'!R11 -> 0 | J14: ='Form Responses 1'!M11 -> 0 | L14: ='Form Responses 1'!K11 -> 0 | N14: ='Form Responses 1'!I11 -> 0 | O14: ='Form Responses 1'!U11 -> 0 | P14: ='Form Responses 1'!S11 -> 0 | Q14: ='Form Responses 1'!N11 -> 0 | R14: ='Form Responses 1'!T11 -> 0 | U14: ='Form Responses 1'!I11 -> 0 | W14: ='Form Responses 1'!J11 -> 0 | X14: ='Form Responses 1'!L11 -> 0 | Z14: ='Form Responses 1'!N11 -> 0 | AA14: ='Form Responses 1'!V11 -> 0 | AF14: ='Form Responses 1'!E11 -> H-5 | AI14: ='Form Responses 1'!H11 -> 0 | AW14: ='Form Responses 1'!F11 -> 48575443BB24C6B3
A15: ='Form Responses 1'!A12 -> 46070.433 | B15: ='Form Responses 1'!C12 -> 20067876 | F15: ='Form Responses 1'!O12 -> 0 | G15: ='Form Responses 1'!P12 -> 0 | H15: ='Form Responses 1'!Q12 -> 0 | I15: ='Form Responses 1'!R12 -> 0 | J15: ='Form Responses 1'!M12 -> 1 | L15: ='Form Responses 1'!K12 -> 1 | N15: ='Form Responses 1'!I12 -> 0 | O15: ='Form Responses 1'!U12 -> 0 | P15: ='Form Responses 1'!S12 -> 0 | Q15: ='Form Responses 1'!N12 -> 0 | R15: ='Form Responses 1'!T12 -> 0 | U15: ='Form Responses 1'!I12 -> 0 | W15: ='Form Responses 1'!J12 -> 0 | X15: ='Form Responses 1'!L12 -> 0 | Z15: ='Form Responses 1'!N12 -> 0 | AA15: ='Form Responses 1'!V12 -> 0 | AF15: ='Form Responses 1'!E12 | AI15: ='Form Responses 1'!H12 -> 0 | AW15: ='Form Responses 1'!F12
A16: ='Form Responses 1'!A13 -> 46070.435 | B16: ='Form Responses 1'!C13 -> 20067825 | F16: ='Form Responses 1'!O13 -> 0 | G16: ='Form Responses 1'!P13 -> 0 | H16: ='Form Responses 1'!Q13 -> 0 | I16: ='Form Responses 1'!R13 -> 0 | J16: ='Form Responses 1'!M13 -> 0 | L16: ='Form Responses 1'!K13 -> 0 | N16: ='Form Responses 1'!I13 -> 0 | O16: ='Form Responses 1'!U13 -> 0 | P16: ='Form Responses 1'!S13 -> 0 | Q16: ='Form Responses 1'!N13 -> 1 | R16: ='Form Responses 1'!T13 -> 0 | U16: ='Form Responses 1'!I13 -> 0 | W16: ='Form Responses 1'!J13 -> 0 | X16: ='Form Responses 1'!L13 -> 0 | Z16: ='Form Responses 1'!N13 -> 1 | AA16: ='Form Responses 1'!V13 -> 0 | AF16: ='Form Responses 1'!E13 | AI16: ='Form Responses 1'!H13 -> 0 | AW16: ='Form Responses 1'!F13
A17: ='Form Responses 1'!A14 -> 46070.52 | B17: ='Form Responses 1'!C14 -> 20067811 | F17: ='Form Responses 1'!O14 | G17: ='Form Responses 1'!P14 | H17: ='Form Responses 1'!Q14 | I17: ='Form Responses 1'!R14 | J17: ='Form Responses 1'!M14 | L17: ='Form Responses 1'!K14 | N17: ='Form Responses 1'!I14 | O17: ='Form Responses 1'!U14 | P17: ='Form Responses 1'!S14 | Q17: ='Form Responses 1'!N14 | R17: ='Form Responses 1'!T14 | U17: ='Form Responses 1'!I14 | W17: ='Form Responses 1'!J14 | X17: ='Form Responses 1'!L14 | Z17: ='Form Responses 1'!N14 | AA17: ='Form Responses 1'!V14 | AF17: ='Form Responses 1'!E14 | AI17: ='Form Responses 1'!H14 -> 1 | AW17: ='Form Responses 1'!F14
... A22: ='Form Responses 1'!A19 -> 46070.526 | B22: ='Form Responses 1'!C19 -> 20067924 | F22: ='Form Responses 1'!O19 | G22: ='Form Responses 1'!P19 | H22: ='Form Responses 1'!Q19 | I22: ='Form Responses 1'!R19 | J22: ='Form Responses 1'!M19 | L22: ='Form Responses 1'!K19 -> 1 | N22: ='Form Responses 1'!I19 | O22: ='Form Responses 1'!U19 | P22: ='Form Responses 1'!S19 | Q22: ='Form Responses 1'!N19 | R22: ='Form Responses 1'!T19 | U22: ='Form Responses 1'!I19 | W22: ='Form Responses 1'!J19 -> 1 | X22: ='Form Responses 1'!L19 -> 55m | Z22: ='Form Responses 1'!N19 | AA22: ='Form Responses 1'!V19 | AF22: ='Form Responses 1'!E19 | AI22: ='Form Responses 1'!H19 | AW22: ='Form Responses 1'!F19
A23: ='Form Responses 1'!A21 -> 46070.744 | B23: ='Form Responses 1'!C21 -> 20067995 | F23: ='Form Responses 1'!O21 | G23: ='Form Responses 1'!P21 | H23: ='Form Responses 1'!Q21 | I23: ='Form Responses 1'!R21 | J23: ='Form Responses 1'!M21 | L23: ='Form Responses 1'!K21 -> 1 | N23: ='Form Responses 1'!I21 | O23: ='Form Responses 1'!U21 | P23: ='Form Responses 1'!S21 | Q23: ='Form Responses 1'!N21 | R23: ='Form Responses 1'!T21 | U23: ='Form Responses 1'!I21 | W23: ='Form Responses 1'!J21 -> 1 | X23: ='Form Responses 1'!L21 | Z23: ='Form Responses 1'!N21 | AA23: ='Form Responses 1'!V21 | AF23: ='Form Responses 1'!E21 | AI23: ='Form Responses 1'!H21 | AW23: ='Form Responses 1'!F21
A24: ='Form Responses 1'!A22 -> 46070.764 | B24: ='Form Responses 1'!C22 -> 20067994 | F24: ='Form Responses 1'!O22 | G24: ='Form Responses 1'!P22 | H24: ='Form Responses 1'!Q22 | I24: ='Form Responses 1'!R22 | J24: ='Form Responses 1'!M22 | L24: ='Form Responses 1'!K22 | N24: ='Form Responses 1'!I22 | O24: ='Form Responses 1'!U22 | P24: ='Form Responses 1'!S22 | Q24: ='Form Responses 1'!N22 | R24: ='Form Responses 1'!T22 | U24: ='Form Responses 1'!I22 | W24: ='Form Responses 1'!J22 | X24: ='Form Responses 1'!L22 | Z24: ='Form Responses 1'!N22 | AA24: ='Form Responses 1'!V22 | AF24: ='Form Responses 1'!E22 -> WiFi-6 | AI24: ='Form Responses 1'!H22 | AW24: ='Form Responses 1'!F22 -> 4857544344E8B0B3
A25: ='Form Responses 1'!A23 -> 46070.833 | B25: ='Form Responses 1'!C23 -> 20068009 | F25: ='Form Responses 1'!O23 | G25: ='Form Responses 1'!P23 | H25: ='Form Responses 1'!Q23 | I25: ='Form Responses 1'!R23 | J25: ='Form Responses 1'!M23 | L25: ='Form Responses 1'!K23 | N25: ='Form Responses 1'!I23 | O25: ='Form Responses 1'!U23 | P25: ='Form Responses 1'!S23 | Q25: ='Form Responses 1'!N23 | R25: ='Form Responses 1'!T23 | U25: ='Form Responses 1'!I23 | W25: ='Form Responses 1'!J23 | X25: ='Form Responses 1'!L23 | Z25: ='Form Responses 1'!N23 | AA25: ='Form Responses 1'!V23 | AF25: ='Form Responses 1'!E23 | AI25: ='Form Responses 1'!H23 -> 1 | AW25: ='Form Responses 1'!F23
A26: ='Form Responses 1'!A24 -> 46071.43 | B26: ='Form Responses 1'!C24 -> 20067983 | F26: ='Form Responses 1'!O24 | G26: ='Form Responses 1'!P24 | H26: ='Form Responses 1'!Q24 | I26: ='Form Responses 1'!R24 | J26: ='Form Responses 1'!M24 | L26: ='Form Responses 1'!K24 | N26: ='Form Responses 1'!I24 | O26: ='Form Responses 1'!U24 | P26: ='Form Responses 1'!S24 | Q26: ='Form Responses 1'!N24 | R26: ='Form Responses 1'!T24 | U26: ='Form Responses 1'!I24 | W26: ='Form Responses 1'!J24 | X26: ='Form Responses 1'!L24 | Z26: ='Form Responses 1'!N24 | AA26: ='Form Responses 1'!V24 | AF26: ='Form Responses 1'!E24 -> FTTR Master ONT | AI26: ='Form Responses 1'!H24 | AW26: ='Form Responses 1'!F24 -> 48575443FBAB0CB6
A27: ='Form Responses 1'!A25 -> 46071.431 | B27: ='Form Responses 1'!C25 -> 20067991 | F27: ='Form Responses 1'!O25 | G27: ='Form Responses 1'!P25 | H27: ='Form Responses 1'!Q25 | I27: ='Form Responses 1'!R25 | J27: ='Form Responses 1'!M25 | L27: ='Form Responses 1'!K25 | N27: ='Form Responses 1'!I25 | O27: ='Form Responses 1'!U25 | P27: ='Form Responses 1'!S25 | Q27: ='Form Responses 1'!N25 | R27: ='Form Responses 1'!T25 | U27: ='Form Responses 1'!I25 | W27: ='Form Responses 1'!J25 | X27: ='Form Responses 1'!L25 | Z27: ='Form Responses 1'!N25 | AA27: ='Form Responses 1'!V25 | AF27: ='Form Responses 1'!E25 | AI27: ='Form Responses 1'!H25 | AW27: ='Form Responses 1'!F25
A28: ='Form Responses 1'!A26 -> 46071.431 | B28: ='Form Responses 1'!C26 -> 20067979 | F28: ='Form Responses 1'!O26 | G28: ='Form Responses 1'!P26 | H28: ='Form Responses 1'!Q26 | I28: ='Form Responses 1'!R26 | J28: ='Form Responses 1'!M26 | L28: ='Form Responses 1'!K26 | N28: ='Form Responses 1'!I26 | O28: ='Form Responses 1'!U26 | P28: ='Form Responses 1'!S26 | Q28: ='Form Responses 1'!N26 | R28: ='Form Responses 1'!T26 | U28: ='Form Responses 1'!I26 | W28: ='Form Responses 1'!J26 | X28: ='Form Responses 1'!L26 | Z28: ='Form Responses 1'!N26 | AA28: ='Form Responses 1'!V26 | AF28: ='Form Responses 1'!E26 | AI28: ='Form Responses 1'!H26 -> 1 | AW28: ='Form Responses 1'!F26
A29: ='Form Responses 1'!A27 -> 46071.432 | B29: ='Form Responses 1'!C27 -> 20067928 | F29: ='Form Responses 1'!O27 | G29: ='Form Responses 1'!P27 | H29: ='Form Responses 1'!Q27 | I29: ='Form Responses 1'!R27 | J29: ='Form Responses 1'!M27 | L29: ='Form Responses 1'!K27 | N29: ='Form Responses 1'!I27 | O29: ='Form Responses 1'!U27 | P29: ='Form Responses 1'!S27 | Q29: ='Form Responses 1'!N27 | R29: ='Form Responses 1'!T27 | U29: ='Form Responses 1'!I27 | W29: ='Form Responses 1'!J27 | X29: ='Form Responses 1'!L27 | Z29: ='Form Responses 1'!N27 | AA29: ='Form Responses 1'!V27 | AF29: ='Form Responses 1'!E27 | AI29: ='Form Responses 1'!H27 | AW29: ='Form Responses 1'!F27
A30: ='Form Responses 1'!A28 -> 46071.432 | B30: ='Form Responses 1'!C28 -> 20067943 | F30: ='Form Responses 1'!O28 | G30: ='Form Responses 1'!P28 | H30: ='Form Responses 1'!Q28 | I30: ='Form Responses 1'!R28 | J30: ='Form Responses 1'!M28 | L30: ='Form Responses 1'!K28 -> 1 | N30: ='Form Responses 1'!I28 | O30: ='Form Responses 1'!U28 | P30: ='Form Responses 1'!S28 | Q30: ='Form Responses 1'!N28 -> 1 | R30: ='Form Responses 1'!T28 | U30: ='Form Responses 1'!I28 | W30: ='Form Responses 1'!J28 -> 1 | X30: ='Form Responses 1'!L28 -> 25 | Z30: ='Form Responses 1'!N28 -> 1 | AA30: ='Form Responses 1'!V28 | AF30: ='Form Responses 1'!E28 | AI30: ='Form Responses 1'!H28 | AW30: ='Form Responses 1'!F28
A31: ='Form Responses 1'!A29 -> 46071.433 | B31: ='Form Responses 1'!C29 -> 20067942 | F31: ='Form Responses 1'!O29 | G31: ='Form Responses 1'!P29 | H31: ='Form Responses 1'!Q29 | I31: ='Form Responses 1'!R29 | J31: ='Form Responses 1'!M29 | L31: ='Form Responses 1'!K29 -> 1 | N31: ='Form Responses 1'!I29 | O31: ='Form Responses 1'!U29 | P31: ='Form Responses 1'!S29 | Q31: ='Form Responses 1'!N29 | R31: ='Form Responses 1'!T29 | U31: ='Form Responses 1'!I29 | W31: ='Form Responses 1'!J29 -> 1 | X31: ='Form Responses 1'!L29 | Z31: ='Form Responses 1'!N29 | AA31: ='Form Responses 1'!V29 | AF31: ='Form Responses 1'!E29 | AI31: ='Form Responses 1'!H29 | AW31: ='Form Responses 1'!F29
A32: ='Form Responses 1'!A30 -> 46071.433 | B32: ='Form Responses 1'!C30 -> 20067931 | F32: ='Form Responses 1'!O30 | G32: ='Form Responses 1'!P30 | H32: ='Form Responses 1'!Q30 | I32: ='Form Responses 1'!R30 | J32: ='Form Responses 1'!M30 | L32: ='Form Responses 1'!K30 -> 1 | N32: ='Form Responses 1'!I30 | O32: ='Form Responses 1'!U30 | P32: ='Form Responses 1'!S30 | Q32: ='Form Responses 1'!N30 | R32: ='Form Responses 1'!T30 | U32: ='Form Responses 1'!I30 | W32: ='Form Responses 1'!J30 | X32: ='Form Responses 1'!L30 | Z32: ='Form Responses 1'!N30 | AA32: ='Form Responses 1'!V30 | AF32: ='Form Responses 1'!E30 | AI32: ='Form Responses 1'!H30 | AW32: ='Form Responses 1'!F30
A33: ='Form Responses 1'!A31 -> 46071.811 | B33: ='Form Responses 1'!C31 -> 20068086 | F33: ='Form Responses 1'!O31 | G33: ='Form Responses 1'!P31 | H33: ='Form Responses 1'!Q31 | I33: ='Form Responses 1'!R31 | J33: ='Form Responses 1'!M31 | L33: ='Form Responses 1'!K31 | N33: ='Form Responses 1'!I31 | O33: ='Form Responses 1'!U31 | P33: ='Form Responses 1'!S31 | Q33: ='Form Responses 1'!N31 -> 1 | R33: ='Form Responses 1'!T31 | U33: ='Form Responses 1'!I31 | W33: ='Form Responses 1'!J31 | X33: ='Form Responses 1'!L31 | Z33: ='Form Responses 1'!N31 -> 1 | AA33: ='Form Responses 1'!V31 | AF33: ='Form Responses 1'!E31 | AI33: ='Form Responses 1'!H31 | AW33: ='Form Responses 1'!F31
A34: ='Form Responses 1'!A32 -> 46071.811 | B34: ='Form Responses 1'!C32 -> 20068087 | F34: ='Form Responses 1'!O32 | G34: ='Form Responses 1'!P32 | H34: ='Form Responses 1'!Q32 | I34: ='Form Responses 1'!R32 | J34: ='Form Responses 1'!M32 | L34: ='Form Responses 1'!K32 -> 1 | N34: ='Form Responses 1'!I32 | O34: ='Form Responses 1'!U32 | P34: ='Form Responses 1'!S32 | Q34: ='Form Responses 1'!N32 | R34: ='Form Responses 1'!T32 | U34: ='Form Responses 1'!I32 | W34: ='Form Responses 1'!J32 | X34: ='Form Responses 1'!L32 | Z34: ='Form Responses 1'!N32 | AA34: ='Form Responses 1'!V32 | AF34: ='Form Responses 1'!E32 | AI34: ='Form Responses 1'!H32 | AW34: ='Form Responses 1'!F32
... A41: ='Form Responses 1'!A39 -> 46071.832 | B41: ='Form Responses 1'!C39 -> 20068057 | F41: ='Form Responses 1'!O39 | G41: ='Form Responses 1'!P39 | H41: ='Form Responses 1'!Q39 | I41: ='Form Responses 1'!R39 | J41: ='Form Responses 1'!M39 | L41: ='Form Responses 1'!K39 | N41: ='Form Responses 1'!I39 | O41: ='Form Responses 1'!U39 | P41: ='Form Responses 1'!S39 | Q41: ='Form Responses 1'!N39 | R41: ='Form Responses 1'!T39 | U41: ='Form Responses 1'!I39 | W41: ='Form Responses 1'!J39 | X41: ='Form Responses 1'!L39 | Z41: ='Form Responses 1'!N39 | AA41: ='Form Responses 1'!V39 | AF41: ='Form Responses 1'!E39 -> 2G | AI41: ='Form Responses 1'!H39 | AW41: ='Form Responses 1'!F39 -> SN:48575443400E3DB1
A42: ='Form Responses 1'!A40 -> 46071.833 | B42: ='Form Responses 1'!C40 -> 20067846 | F42: ='Form Responses 1'!O40 | G42: ='Form Responses 1'!P40 | H42: ='Form Responses 1'!Q40 | I42: ='Form Responses 1'!R40 | J42: ='Form Responses 1'!M40 | L42: 1 | N42: ='Form Responses 1'!I40 | O42: ='Form Responses 1'!U40 | P42: ='Form Responses 1'!S40 | Q42: ='Form Responses 1'!N40 | R42: ='Form Responses 1'!T40 | U42: ='Form Responses 1'!I40 | W42: 1 | X42: ='Form Responses 1'!L40 | Z42: ='Form Responses 1'!N40 | AA42: ='Form Responses 1'!V40 | AF42: ='Form Responses 1'!E40 -> FTTR Master ONT | AI42: ='Form Responses 1'!H40 | AW42: ='Form Responses 1'!F40 -> sn:48575443FBA7CDB6
A43: ='Form Responses 1'!A41 -> 46071.833 | B43: ='Form Responses 1'!C41 -> 20068089 | F43: ='Form Responses 1'!O41 | G43: ='Form Responses 1'!P41 | H43: ='Form Responses 1'!Q41 | I43: ='Form Responses 1'!R41 | J43: ='Form Responses 1'!M41 | L43: ='Form Responses 1'!K41 | N43: ='Form Responses 1'!I41 | O43: ='Form Responses 1'!U41 | P43: ='Form Responses 1'!S41 | Q43: ='Form Responses 1'!N41 | R43: ='Form Responses 1'!T41 | U43: ='Form Responses 1'!I41 | W43: ='Form Responses 1'!J41 | X43: ='Form Responses 1'!L41 | Z43: ='Form Responses 1'!N41 | AA43: ='Form Responses 1'!V41 | AF43: ='Form Responses 1'!E41 | AI43: ='Form Responses 1'!H41 -> 1 | AW43: ='Form Responses 1'!F41
A44: ='Form Responses 1'!A42 -> 46071.834 | B44: ='Form Responses 1'!C42 -> 20068116 | F44: ='Form Responses 1'!O42 | G44: ='Form Responses 1'!P42 | H44: ='Form Responses 1'!Q42 | I44: ='Form Responses 1'!R42 | J44: ='Form Responses 1'!M42 | L44: ='Form Responses 1'!K42 | N44: ='Form Responses 1'!I42 | O44: ='Form Responses 1'!U42 | P44: ='Form Responses 1'!S42 | Q44: ='Form Responses 1'!N42 -> 1 | R44: ='Form Responses 1'!T42 | U44: ='Form Responses 1'!I42 | W44: ='Form Responses 1'!J42 | X44: ='Form Responses 1'!L42 | Z44: ='Form Responses 1'!N42 -> 1 | AA44: ='Form Responses 1'!V42 | AF44: ='Form Responses 1'!E42 | AI44: ='Form Responses 1'!H42 | AW44: ='Form Responses 1'!F42
A45: ='Form Responses 1'!A43 -> 46072.949 | B45: ='Form Responses 1'!C43 -> 20068167 | F45: ='Form Responses 1'!O43 | G45: ='Form Responses 1'!P43 | H45: ='Form Responses 1'!Q43 | I45: ='Form Responses 1'!R43 | J45: ='Form Responses 1'!M43 | L45: ='Form Responses 1'!K43 | N45: ='Form Responses 1'!I43 | O45: ='Form Responses 1'!U43 | P45: ='Form Responses 1'!S43 | Q45: ='Form Responses 1'!N43 | R45: ='Form Responses 1'!T43 | U45: ='Form Responses 1'!I43 | W45: ='Form Responses 1'!J43 | X45: ='Form Responses 1'!L43 | Z45: ='Form Responses 1'!N43 | AA45: ='Form Responses 1'!V43 | AF45: ='Form Responses 1'!E43 -> FTTR Master ONT | AI45: ='Form Responses 1'!H43 | AW45: ='Form Responses 1'!F43 -> 48675443FBAA50B6
A46: ='Form Responses 1'!A44 -> 46072.95 | B46: ='Form Responses 1'!C44 -> 20068127 | F46: ='Form Responses 1'!O44 | G46: ='Form Responses 1'!P44 | H46: ='Form Responses 1'!Q44 | I46: ='Form Responses 1'!R44 | J46: ='Form Responses 1'!M44 | L46: ='Form Responses 1'!K44 | N46: ='Form Responses 1'!I44 | O46: ='Form Responses 1'!U44 | P46: ='Form Responses 1'!S44 | Q46: ='Form Responses 1'!N44 | R46: ='Form Responses 1'!T44 | U46: ='Form Responses 1'!I44 | W46: ='Form Responses 1'!J44 | X46: ='Form Responses 1'!L44 | Z46: ='Form Responses 1'!N44 | AA46: ='Form Responses 1'!V44 -> 1 | AF46: ='Form Responses 1'!E44 | AI46: ='Form Responses 1'!H44 | AW46: ='Form Responses 1'!F44
A47: ='Form Responses 1'!A45 -> 46072.95 | B47: ='Form Responses 1'!C45 -> 20068183 | F47: ='Form Responses 1'!O45 | G47: ='Form Responses 1'!P45 | H47: ='Form Responses 1'!Q45 | I47: ='Form Responses 1'!R45 | J47: ='Form Responses 1'!M45 | L47: ='Form Responses 1'!K45 | N47: ='Form Responses 1'!I45 | O47: ='Form Responses 1'!U45 | P47: ='Form Responses 1'!S45 | Q47: ='Form Responses 1'!N45 -> 1 | R47: ='Form Responses 1'!T45 | U47: ='Form Responses 1'!I45 | W47: ='Form Responses 1'!J45 | X47: ='Form Responses 1'!L45 | Z47: ='Form Responses 1'!N45 -> 1 | AA47: ='Form Responses 1'!V45 | AF47: ='Form Responses 1'!E45 | AI47: ='Form Responses 1'!H45 | AW47: ='Form Responses 1'!F45
A48: ='Form Responses 1'!A46 -> 46072.951 | B48: ='Form Responses 1'!C46 -> 20068150 | F48: ='Form Responses 1'!O46 | G48: ='Form Responses 1'!P46 | H48: ='Form Responses 1'!Q46 | I48: ='Form Responses 1'!R46 | J48: ='Form Responses 1'!M46 | L48: ='Form Responses 1'!K46 -> 1 | N48: ='Form Responses 1'!I46 | O48: ='Form Responses 1'!U46 | P48: ='Form Responses 1'!S46 | Q48: ='Form Responses 1'!N46 | R48: ='Form Responses 1'!T46 | U48: ='Form Responses 1'!I46 | W48: ='Form Responses 1'!J46 -> 1 | X48: ='Form Responses 1'!L46 | Z48: ='Form Responses 1'!N46 | AA48: ='Form Responses 1'!V46 | AF48: ='Form Responses 1'!E46 | AI48: ='Form Responses 1'!H46 | AW48: ='Form Responses 1'!F46
A49: ='Form Responses 1'!A47 -> 46072.951 | B49: ='Form Responses 1'!C47 -> 20068082 | F49: ='Form Responses 1'!O47 | G49: ='Form Responses 1'!P47 | H49: ='Form Responses 1'!Q47 | I49: ='Form Responses 1'!R47 | J49: ='Form Responses 1'!M47 | L49: ='Form Responses 1'!K47 | N49: ='Form Responses 1'!I47 | O49: ='Form Responses 1'!U47 | P49: ='Form Responses 1'!S47 | Q49: ='Form Responses 1'!N47 | R49: ='Form Responses 1'!T47 | U49: ='Form Responses 1'!I47 | W49: ='Form Responses 1'!J47 | X49: ='Form Responses 1'!L47 | Z49: ='Form Responses 1'!N47 | AA49: ='Form Responses 1'!V47 -> 1 | AF49: ='Form Responses 1'!E47 | AI49: ='Form Responses 1'!H47 | AW49: ='Form Responses 1'!F47
A50: ='Form Responses 1'!A48 -> 46074.395 | B50: ='Form Responses 1'!C48 -> 20068137 | F50: ='Form Responses 1'!O48 | G50: ='Form Responses 1'!P48 | H50: ='Form Responses 1'!Q48 | I50: ='Form Responses 1'!R48 | J50: ='Form Responses 1'!M48 | L50: ='Form Responses 1'!K48 | N50: ='Form Responses 1'!I48 | O50: ='Form Responses 1'!U48 | P50: ='Form Responses 1'!S48 | Q50: ='Form Responses 1'!N48 | R50: ='Form Responses 1'!T48 | U50: ='Form Responses 1'!I48 | W50: ='Form Responses 1'!J48 | X50: ='Form Responses 1'!L48 | Z50: ='Form Responses 1'!N48 | AA50: ='Form Responses 1'!V48 | AF50: ='Form Responses 1'!E48 | AI50: ='Form Responses 1'!H48 -> 1 | AW50: ='Form Responses 1'!F48
...
