Workbook

Sheet March 2026
A1: Date | B1: Team | C1: Controller | D1: Ticket No | E1: Package | F1: Exchange | G1: Block | H1: Road | I1: Bldg | J1: Flat | K1: Fault Description from LO | L1: Mobile | M1: Description | N1: Service Type (List) | O1: LO Name (List) | P1: Creationdate/time | Q1: Assigned Date/Time | R1: Close Date/Time | S1: SLA From creation time | T1: KPI Status (Automated) | U1: Reason (If Exceeded) | V1: Circuit | X1: Root Cause | Y1: Resolution (List) | Z1: Resolution Description | AA1: Non-Genuine Ticket | AB1: Call_Time | AC1: Faulty/damaged | AD1: ONT Model | AE1: SN OLD ONT | AF1: New SN No As Per NCE | AG1: ONT Protection Box | AH1: SAAS Type | AI1: Box Number | AJ1: Final remarks - ANISA
A2: 46113 | B2: Bilal | C2: Controller Yasser | D2: 20071811 | E2: ESSENTIAL_300M_60M | F2: BUD | G2: 514 | H2: 1472 | I2: 4061 | J2: 0 | K2: LOS | L2: 33887756 | M2: Appointment 01/04/2026@call before visit called customer and customer said there disconnection and slow internet .she wants a team to check the internet Rx Optical Power (dBm) = -17.95 | N2: GPON Service Assurance | O2: Batelco | P2: 46113.333 | Q2: 46113.459 | R2: 46113.65 | S2: 0.31700231 | T2: Within | V2: WBS_747887_1 | W2: Resolved | X2: No Issue found on site visit | Z2: customer complained about disconnection during our visit we checked the line end-to-end and found there is configuration issue we reconfigured the ont and now line working fine and customer need to more coverage we recommend the Redbox now customer satisfied | AA2: Non Geniune | AC2: Damaged | AJ2: Not required
A3: 46113 | B3: Bilal | C3: Controller Yasser | D3: 20071831 | E3: ESSENTIAL_300M_60M | F3: BUD | G3: 580 | H3: 8015 | I3: 1450 | J3: 0 | K3: the customer is router is very old and gets dissconected and it has been two months with this issue and he says he received message before to replace it but he didn't, note that he raised complains before and they restarted his line but he still face the same issue | L3: 36753325-39991148 | M3: Appointment 01/04/2026@call before visit called customer and customer said there disconnection and slow internet .she wants a team to check the internet | N3: GPON Service Assurance | O3: Batelco | P3: 46113.501 | Q3: 46113.625 | R3: 46113.781 | S3: 0.28064815 | T3: Within | V3: 17699343 | W3: Resolved | X3: No Issue found on site visit | Z3: customer complained about the disconnection during our visit we checked the line end-to-end and there no technical issue found ont working properly customer have extender that i found disconnect so we reconnected again and explained to customer haw to connect the extender now customer satisfied.. | AA3: Non Geniune | AC3: Damaged | AJ3: Not required
A4: 46114 | B4: Rajesh | C4: Controller Yasser | D4: 20071913 | E4: ESSENTIAL_300M_60M | F4: ROW | G4: 1208 | H4: 810 | I4: 609 | J4: 0 | K4: Customer reported internet keep on disconnecting every few minutes // Customer confirmed red light come and go | L4: 39811104 | M4: Appointment 02/04/2026@call and visit after 2 pm internet keep disconnection as per the customer he wants a team to visit Rx Optical Power (dBm) = -14.67 | N4: GPON Service Assurance | O4: Batelco | P4: 46113.894 | Q4: 46114.018 | R4: 46114.647 | S4: 0.75320602 | T4: With in | V4: WBS_332496_1 | W4: Resolved | X4: No Issue found on site visit | Z4: As per our visit for the disconnection issue, we checked the connection end-to-end and verified line stability and RX power; all parameters are normal. We tested the speed via LAN and WiFi, and both are as per the subscribed package. A ping test was also performed, and no disconnection was observed. The customer reported experiencing a disconnection issue yesterday evening; however, during our visit, no issue was found. At our end, all services are working properly. | AA4: Non-Genuine Ticket | AC4: Damaged | AJ4: Not required
A5: 46114 | B5: rajesh | C5: Controller Yasser | D5: 20071956 | E5: ESSENTIAL_300M_60M | F5: ROW | G5: 1215 | H5: 1516 | I5: 1076 | J5: 0 | K5: customer complaining about a slow speed | L5: 33044140 | M5: App:2 April 2026/ open time as per customer line is working and it goes off and he is requseting a team to visit him and current it is not showing in NCE | N5: GPON Service Assurance | O5: STC | P5: 46114.473 | Q5: 46114.473 | R5: 46114.634 | S5: 0.16111111 | T5: With in | V5: WBS_673812_1 | W5: Resolved | X5: No Issue found on site visit | Z5: As per our visit for the disconnection issue, we checked the connection end-to-end and verified line stability and RX power; all parameters are normal. During our inspection, we found that the customer was using a LAN cable from the ONT to a WiFi extender. The LAN cable was causing a loop issue—whenever it was connected, the ONT experienced repeated no-browsing problems. We removed the LAN cable and advised the customer to either replace it or avoid using that cable. After this, the connection is stable, and speed is as per the subscribed package. From our side, all services are working properly. | AA5: Non-Genuine Ticket | AB5: 0.48958333 | AC5: Damaged | AJ5: Not required
A6: 46114 | B6: Mohsin | C6: Controller Yasser | D6: 20071804 | E6: ESSENTIAL_500M_250M | F6: BUD | G6: 565 | H6: 6525 | I6: 809 | J6: 0 | K6: LOS | L6: 36363633 | M6: No answer-1 Kindly note the work done. No answer-1 LOS | N6: GPON Service Assurance | O6: Batelco | P6: 46113.135 | Q6: 46113.26 | R6: 46114.692 | S6: 1.5568634 | T6: Within | U6: Maintenance Delayed | V6: 77007770 | W6: Resolved | X6: No Issue found on site visit | Z6: As per our visit for the offline issue, we checked the connection end-to-end and verified line stability and RX power; all parameters are normal. Line has been fixed by maintenance team but customer turn off router Cudtomer having issue with tv application we informed him that he have to call maintenance company for the tv to fix it | AC6: Damaged | AJ6: Not required
A7: 46114 | B7: Rajesh | C7: Controller Yasser | D7: 20071976 | E7: ESSENTIAL_300M_60M | F7: ROW | G7: 1204 | H7: 427 | I7: 1815 | J7: 0 | K7: Customer facing disconnection in internet and slowness please check the internet and check the attachment | L7: 39090169 | M7: Appointment 02/04/2026@Before 7 We called the customer and he informed that he is facing disconnection in his line and he wants a team to check Rx Optical Power (dBm) = -16.32 | N7: GPON Service Assurance | O7: Batelco | P7: 46114.58 | Q7: 46114.705 | R7: 46114.782 | S7: 0.20206019 | T7: With in | V7: WBS_384605_1 | W7: Resolved | X7: No Issue found on site visit | Z7: As per our visit regarding the disconnection issue, we checked the connection end-to-end and verified line stability and RX power; all parameters are normal. A ping test was conducted, and no disconnections were observed. We also tested internet speed via both LAN and WiFi, and the speeds are as per the subscribed package. However, the customer is experiencing slow speed inside a room located approximately 16 meters away from the ONT. This is due to the distance from the ONT and the use of 2.4 GHz WiFi, which has limited coverage and performance over longer distances. We recommended that the customer contact the service provider to install a WiFi Access Point (AP) to improve coverage. From our side, everything is working fine. | AA7: Non-Genuine Ticket | AC7: Damaged | AJ7: Not required
A8: 46115 | B8: Zubair | C8: Controller Aditi | D8: 20072054 | E8: ESSENTIAL_300M_60M | F8: NZA | G8: 1214 | H8: 1411 | I8: 706 | J8: 0 | K8: LOS | L8: 37778703 | M8: Appointment 03/04/2026@anytime We called the customer and customer said there is red light on the router LOS | N8: GPON Service Assurance | O8: Batelco | P8: 46115.528 | Q8: 46115.528 | R8: 46115.642 | S8: 0.11413194 | T8: Within | V8: 17224803 | W8: Resolved | X8: GPON_Patch_Cord | Y8: Re-inserted Patch Cord Correctly | Z8: Patch cord was lose in ont we re-insert the patch cord properly now line restored | AC8: Damaged | AJ8: Not required
A9: 46116 | B9: Mohsin | C9: Controller Waqas | D9: 20072066 | E9: ESSENTIAL_300M_60M | F9: BUD | G9: 583 | H9: 8318 | I9: 1749 | J9: 0 | K9: customer claiming router have issue kindly she is requesting for replacement | L9: 36444737 | M9: Appointment 04/04/2026@anytime We called the customer and customer said there is disconnection and speed issue .he sais send a team to check the issue Line is working normal in NCE | N9: GPON Service Assurance | O9: Batelco | P9: 46115.629 | Q9: 46115.754 | R9: 46116.569 | S9: 0.93967593 | T9: Within | U9: Appointment Rescheduled | V9: 17009485 | W9: Resolved | X9: Profile Reconfigured - Hard Reset | Z9: As per customer facing speed issue . Our visit we found speed issue 2.4G and 5G...not getting more then 2.4G 20Mbps and 5G 200Mbps.after reset ONT speed getting as per package.. Now line working fine... | AA9: Non-Genuine Ticket | AJ9: Not required
A10: 46116 | B10: Rajesh | C10: Controller Waqas | D10: 20072084 | E10: ESSENTIAL_300M_60M | F10: ROW | G10: 1209 | H10: 914 | I10: 944 | K10: Customer reported he has been facing issue with internet router and customer prefers visit to his house to further investigate the root of the issue //Customer instead on visiting his house please customer is calling us multiple times regarding the same issu | L10: 33458158 | M10: App:4/4/26 - 3PM/ As per customer internet not working router may b some issue | N10: GPON Service Assurance | O10: Batelco | P10: 46115.854 | Q10: 46115.979 | R10: 46116.646 | S10: 0.79188657 | T10: Within | V10: WBS_727646_1 | W10: Resolved | X10: No Issue found on site visit | Z10: As per our visit for the disconnection issue, we checked the connection end-to-end and verified line stability and RX power; all values are normal. Ping test and speed test through both WiFi and LAN are working fine. During inspection, we found the internal cable had an SC UPC tube connector, which may cause instability. We removed the connector and completed a pigtail fusion splice. After rectification, we tested again and confirmed that speed and ping are normal. Customer reported buffering issue while using TV IP applications; however, from our side, the connection is working properly with no faults detected. | AA10: Non-Genuine Ticket | AJ10: Not required
A11: 46116 | B11: Bilal | C11: Controller Yasser | D11: 20072082 | E11: ESSENTIAL_300M_60M | F11: ROW | G11: 1209 | H11: 903 | I11: 222 | K11: customer facing slow and disconnected internet | L11: 66334100 | M11: App:4/4/26 - Open time/ Customer said there is no signal on ONT and keep disconnection | N11: GPON Service Assurance | O11: Batelco | P11: 46115.794 | Q11: 46115.919 | R11: 46116.588 | S11: 0.79375 | T11: Within | V11: WBS_263750_1 | W11: Resolved | X11: No Issue found on site visit | Z11: customer complained about the disconnection during our visit we checked the line end-to-end over line working properly and the rx power was stable speed everything is working properly no technical issue was found | AA11: Non-Genuine Ticket | AC11: Damaged | AJ11: Not required
A12: 46117 | B12: Bilal | C12: Controller Waqas | D12: 20071941 | E12: ESSENTIAL_1G_500M | F12: NZA | G12: 1038 | H12: 3819 | I12: 467 | K12: no internet connection ,he can connect with wifi but without internet | L12: 32029295 | M12: Appointment 05/04/2026@9 am sharp App 5 April 2026/ 9/ As per customer LAN cable is working but he is unable to conect with wifi and he is asking a team to visit him Customer will arrange IT person because Customer using firewall....Sunday 9am sharp" | N12: GPON Service Assurance | O12: Batelco | P12: 46114.408 | Q12: 46114.532 | R12: 46117.489 | S12: 3.0805903 | T12: Exceeded | U12: Appointment Rescheduled | V12: WBS_754514_1 | W12: Resolved | X12: Customer Internal Nertwork Issue | Y12: No isue found on site visit | Z12: Customer complained about no internet. During our visit, we found that the customer firewall device was faulty. As per customer request, we removed the firewall and connected the service directly to the main ONT. The line is now working fine and stable. and customer satisfied. Customer had an emegency he left and informed our team to send the link he will complete the survey later | AA12: Non-Genuine Ticket | AC12: Faulty | AJ12: Not required
A13: 46118 | B13: Mohsin | C13: Controller Yasser | D13: 20072040 | E13: ESSENTIAL_300M_60M | F13: NZA | G13: 1214 | H13: 1401 | I13: 6 | J13: 0 | K13: The customer facing slowness Kindly check. Download: 130 Mbps. | L13: 33350240 | M13: Appointment 06/04/2026@4 On visit customer reappointment tomorrow after 4 o'clock Direct visit, No access to the ONT, ONT room is closed, customer saying plz come back tomorrow after 4pm Unreachable 2 no answer by call no access by visit | N13: GPON Service Assurance | O13: Batelco | P13: 46115.053 | Q13: 46115.053 | R13: 46118.774 | S13: 3.7202662 | T13: Exceeded | U13: Appointment Rescheduled | V13: WBS_711823_1 | W13: Resolved | X13: No Issue found on site visit | Z13: As per our visit regarding the customer’s complaint of slow browsing, we found that the customer is using a PlayStation connected via Wi-Fi. We informed the customer that for better performance and stability, it is recommended to use a LAN cable instead of Wi-Fi. All parameters were checked and found to be normal. Speed tests were conducted using LAN cable, 2.4GHz Wi-Fi, and 5GHz Wi-Fi, and all results were within the expected range. Currently, the service is working fine. | AA13: Non-Genuine Ticket | AC13: Damaged | AJ13: Not required
A14: 46117 | B14: Zubair | C14: Controller Yasser | D14: 20072226 | E14: ESSENTIAL_300M_60M | F14: JZR | G14: 1056 | H14: 5634 | I14: 1226 | J14: 0 | K14: offline | L14: 33039093 | M14: Appointment 05/04/2026@Anytime We called the customer and customer said there is disconnection and speed issue .he sais send a team to check the issue | N14: GPON Service Assurance | O14: Batelco | P14: 46117.612 | Q14: 46117.737 | R14: 46117.793 | S14: 0.18008102 | T14: Within | V14: 17002740 | W14: Resolved | X14: No Issue found on site visit | Z14: As per the customer's report, the internet is not working and there's a speed issue. However, during our visit, the line was working normally without any issues, and the customer is getting the speed as per their package. The power is normal (20) | AA14: Non-Genuine Ticket | AC14: Damaged | AJ14: Not required
A15: 46118 | B15: Mohsin | C15: Controller Yasser | D15: 20072253 | E15: ESSENTIAL_300M_60M | F15: ROW | G15: 1020 | H15: 2041 | I15: 3564 | J15: 0 | K15: refer to SR-26032863688 after they change the fiber for him the internet get wrost kindly check | L15: 39865544 | M15: Appointment 06/04/2026@anytime We called the customer and customer said there is disconnection and speed issue internet not stable with all devices .he wants a team to check Rx Optical Power (dBm) = -16.73 | N15: GPON Service Assurance | O15: Batelco | P15: 46117.924 | Q15: 46118.049 | R15: 46118.713 | S15: 0.78880787 | T15: Within | V15: WBS_674064_1 | W15: Resolved | X15: No Issue found on site visit | Z15: As per our visit for the disconnection issue, we checked the connection end-to-end and RX power are normal. During our inspection, we found one LAN cables was faulty—when connected directly to the ONT, the internet got disconnected. We informed to customer he will change Lan cable After now connection is working properly. we conducted ping tests and speed tests through both WiFi and LAN, and everything was working fine. | AA15: Non-Genuine Ticket | AC15: Damaged | AJ15: Not required
A16: 46118 | B16: Rajesh | C16: Controller Waqas | D16: 20072252 | E16: ESSENTIAL_300M_60M | F16: NZA | G16: 1038 | H16: 3872 | I16: 3086B | J16: 23 | K16: customer facing slow internet connection | L16: 33163136 | M16: Appointment 06/04/2026@11AM - 12PM We called the customer and customer said that the network displays the name of the wifi but there's no connection | N16: GPON Service Assurance | O16: Batelco | P16: 46117.922 | Q16: 46117.922 | R16: 46118.537 | S16: 0.61503472 | T16: Within | V16: WBS_721378_1 | W16: Resolved | X16: Customer Related Issue | Y16: Customer Internal Network issue | Z16: As per our visit for the disconnection issue and WiFi connectivity issue, we checked the connection end-to-end and verified line stability and RX power; everything is normal. We tested WiFi stability and speed on both 2.4 GHz and 5 GHz bands, and both are working normally and stable. The customer reported that one laptop used for work is unable to connect to WiFi. Upon checking, the issue appears to be with the customer’s device. We explained this to the customer, and he acknowledged and will resolve it through an IT service shop. From our side, no faults were found. | AA16: Non-Genuine Ticket | AB16: 46118.378 | AJ16: Not required
A17: 46118 | B17: Mohsin | C17: Controller Yasser | D17: 20072266 | E17: ESSENTIAL_300M_60M | F17: NZA | G17: 1012 | H17: 101 | I17: 701 | J17: 0 | K17: LOS rx power high | L17: 36602009 | M17: Appointment 06/04/2026@anytime We called the customer and customer said there is red light on the router and telephone line is not working Line not showing in NCE | N17: GPON Service Assurance | O17: Batelco | P17: 46118.374 | Q17: 46118.499 | R17: 46118.578 | S17: 0.20355324 | T17: Within | V17: WBS_372446_1 | W17: Resolved | X17: No Issue found on site visit | Z17: Line is up and connected from ourside this is ISDN line power is also fine . Customer has been informed to check with Businnes team there is no such issue from ourside. | AJ17: Not required
A18: 46118 | B18: Rajesh | C18: Controller Aditi | D18: 20072268 | E18: ESSENTIAL_300M_60M | F18: ROW | G18: 1208 | H18: 808 | I18: 485 | J18: 0 | K18: customer not getting full speed even if he is connected on 5G | L18: 39989869 | M18: Appointment 06/04/2026@anytime We called the customer and customer said there is disconnection and speed issue internet not stable with all devices .he wants a team to check Rx Optical Power (dBm) = -19.35 | N18: GPON Service Assurance | O18: Batelco | P18: 46118.394 | Q18: 46118.519 | R18: 46118.497 | S18: 0.10302083 | T18: Within | V18: WBS_393378_1 | W18: Resolved | X18: No Issue found on site visit | Y18: No Issue found on site visit | Z18: As per our visit for the slowness issue, we checked the connection end-to-end and verified line stability and RX power; everything is normal. The internal FTB and external FTB side cable connections are as per standard. We tested the connection speed through LAN, WiFi 2.4 GHz, and WiFi 5 GHz, and all are working normally with speeds as per the subscribed package. A ping test was also conducted to check for disconnection, and the results were stable with no issues found. The customer reported that at times the WiFi suddenly disappears/disconnects and reconnects after some time. However, during our visit, all services were working properly, and no issue was observed. | AA18: Non-Genuine Ticket | AB18: 46118.409 | AJ18: Not required
A19: 46118 | B19: Mohsin | C19: Controller Aditi | D19: 20072288 | E19: ESSENTIAL_300M_60M | F19: ROW | G19: 1032 | H19: 28 | I19: 63 | K19: Router Offline No lights in router | L19: 36191755 | M19: Appointment 06/04/2026@anytime As per Customer there is no light on ONT and in NCE shows offline | N19: GPON Service Assurance | O19: Batelco | P19: 46118.5 | Q19: 46118.625 | R19: 46118.552 | S19: 0.051724537 | T19: Within | V19: 21020049 | W19: Resolved | X19: No Issue found on site visit | Y19: No Issue found on site visit | Z19: On visit no fault found ont off due to customer main electrical power DP MCB off .we switch on mcb ont working fine ...same inform to customer | AA19: Non-Genuine Ticket | AB19: 46118.506 | AJ19: Not required
A20: 46118 | B20: bilal | C20: Controller Waqas | D20: 20072304 | E20: ESSENTIAL_300M_60M | F20: BUD | G20: 575 | H20: 7527 | I20: 1941 | J20: 21 | K20: Customer facing slowness and disconnection in his internet conection | L20: 33364595 | M20: Appointment 06/04/2026@anytime We called the customer and customer said there is disconnection and speed issue internet not stable with all devices .he wants a team to check Rx Optical Power (dBm) = -11.61 | N20: GPON Service Assurance | O20: Batelco | P20: 46118.585 | Q20: 46118.71 | R20: 46118.689 | S20: 0.10413194 | T20: Within | V20: WBS_376910_1 | W20: Resolved | X20: No Issue found on site visit | Z20: customer complained about the disconnection during our visit we checked the line end-to-end over line working properly we checked speed test with LAN and Wi-Fi both working as per the customer package checked ping test it's not showing any disconnection. customer have issue with his red box we reconfigured the red boxe now customer is satisfied. | AA20: Non-Genuine Ticket | AJ20: Not required
A21: 46118 | B21: Rajesh | C21: Controller Yasser | D21: 20072310 | E21: ESSENTIAL_300M_60M | F21: ROW | G21: 1204 | H21: 415 | I21: 1133 | J21: 0 | K21: router keep disconnecting | L21: 66614665 | M21: Appointment 06/04/2026@anytime We called the customer and customer said there is disconnection and speed issue internet not stable with all devices .he wants a team to check | N21: GPON Service Assurance | O21: Batelco | P21: 46118.623 | Q21: 46118.747 | R21: 46118.681 | S21: 0.058101852 | T21: Within | V21: 17178937 | W21: Resolved | X21: No Issue found on site visit | Z21: As per our visit regarding the disconnection issue, we checked the connection and performed ping tests through both LAN and WiFi. No disconnection was observed during testing. We also conducted speed tests via LAN and WiFi, and all results were within normal limits. The customer is using a TP-Link extender in the kitchen area, which is connected wirelessly (WBS) and not through LAN. We informed the customer to verify whether any future disconnection occurs on the ONT WiFi or the extender. At the time of our visit, no issues were found and all services were working properly. | AA21: Non-Genuine Ticket | AC21: Damaged | AJ21: Not required
A22: 46118 | B22: Rajesh | C22: Controller Yasser | D22: 20072314 | E22: ESSENTIAL_300M_60M | F22: DUM | G22: 1016 | H22: 1606 | I22: 287 | J22: 32 | K22: Customer complaining about latency issue , Before used to get 2 or 3 ms now its 30 ms or above. | L22: 33117905 | M22: Appointment 06/04/2026@anytime We called the customer and customer said there is disconnection and speed issue internet not stable with all devices .he wants a team to check | N22: GPON Service Assurance | O22: STC | P22: 46118.65 | Q22: 46118.65 | R22: 46118.728 | S22: 0.078194444 | T22: Within | V22: WBS_420169_1 | W22: Resolved | X22: No Issue found on site visit | Z22: As per our visit regarding the customer’s slow speed issue and high MS/ping issue on PlayStation, we checked the connection end-to-end and verified line stability and RX power; all parameters were normal. During our investigation, we found that the ONT LAN ports were providing a maximum speed of 100/40 Mbps, whereas the subscribed package speed is 300/60 Mbps. We reset and reconfigured the ONT, after which all LAN ports were delivering the expected speed. However, the customer is still experiencing high MS/ping issues while gaming on PlayStation. From our side, all tests, including ping tests, show stable connectivity with no disconnection. The customer has been informed to contact the service provider regarding the gaming server/ping issue. | AA22: Non-Genuine Ticket | AC22: Damaged | AJ22: Not required
A23: 46119 | B23: Bilal | C23: Controller Aditi | D23: 20072312 | E23: ESSENTIAL_300M_60M | F23: BUD | G23: 533 | H23: 3314 | I23: 484 | J23: 0 | K23: The customer has been using fiber service with us since 2022, and before that, he used the same ONT with another company. Now, the customer noticed there is a disconnection issue, and the ONT is not working well. Please check the ONT and replace the device if required. | L23: 39670182 | M23: Appointment 07/04/2026@ 8 to 4- As per customer he is facing speed and disonnection issue sometimes need to restart the ONT he need a team to visit him | N23: GPON Service Assurance | O23: STC | P23: 46118.63 | Q23: 46118.63 | R23: 46119.402 | S23: 0.7721875 | T23: within | V23: WBS_393458_1 | W23: Resolved | X23: No Issue found on site visit | Y23: No Issue found on site visit | Z23: Customer complained about disconnection. During our visit, we checked the line end-to-end and found the power stable. We performed speed tests on both Wi-Fi and LAN cable and obtained proper speed as per the customer package. We also conducted a ping test, which was working properly. Overall, the line and ONT are working properly. | AA23: Non-Genuine Ticket | AB23: 46118.639 | AJ23: Not required
A24: 46119 | B24: Rajesh | C24: Controller Waqas | D24: 20072343 | E24: ESSENTIAL_300M_60M | F24: ROW | G24: 1033 | H24: 3367 | I24: 2678 | J24: 0 | K24: RX power-22.4dBm | L24: 39262696 | M24: Appointment 07/04/2026@after 4 We called the customer and customer said there is disconnection and speed issue internet not stable with all devices .he wants a team to check Rx Optical Power (dBm) = -22.52 | N24: GPON Service Assurance | O24: Batelco | P24: 46118.824 | Q24: 46118.948 | R24: 46119.714 | S24: 0.89052083 | T24: within | V24: 21019495 | W24: Resolved | X24: Customer Related Issue | Y24: Customer internal Network Issue | Z24: Visited for disconnection issue. Checked end-to-end connection, line stability, and RX power – all normal. Performed ping and speed tests via WiFi and LAN; results were fine. Found internal FTB using SC UPC tube connector, which may cause instability. Removed connector and completed pigtail fusion splice. Rechecked ping and speed – working normally. Customer premises is large; main ONT installed on 1st floor does not provide full coverage. Ground floor using WiFi extender via WPS. Advised customer to contact service provider for proper WiFi access point installation. From our side, connection is stable and working fine. | AA24: Non-Genuine Ticket | AJ24: Not required
A25: 46119 | B25: Mohsin | C25: Controller Aditi | D25: 20072374 | E25: ESSENTIAL_300M_60M | F25: HAM | G25: 1014 | H25: 6 | I25: 27 | J25: 1 | K25: customer connect with wifi but there is no internet connection ,if we restart the router working only for two minutes after that disconnected again | L25: 33402526 | M25: Appointment 07/04/2026@anytime We called the customer and customer said there is disconnection and speed issue internet not stable with all devices .he wants a team to check Rx Optical Power (dBm) = -17.3 | N25: GPON Service Assurance | O25: Batelco | P25: 46119.416 | Q25: 46119.54 | R25: 46119.479 | S25: 0.063263889 | T25: within | V25: WBS_379745_1 | W25: Resolved | X25: No Issue found on site visit | Y25: No Issue found on site visit | Z25: On visit As per customer said wifi SSID name and Password showing line number ..reconfiguration SSID and password as per customer now line working fine | AA25: Non-Genuine Ticket | AB25: 46119.422 | AJ25: Not required
A26: 46119 | B26: Mohsin | C26: Controller Yasser | D26: 20072425 | E26: ESSENTIAL_300M_60M | F26: NZA | G26: 1214 | H26: 1447 | I26: 2902 | J26: 0 | K26: los + offline in tr69 | L26: 33330234 | M26: Appointment 07/04/2026@Anytime We called the customer and customer said there is disconnection and speed issue internet not stable with all devices .he wants a team to check Rx Optical Power (dBm) = -18.76 | N26: GPON Service Assurance | O26: Batelco | P26: 46119.672 | Q26: 46119.796 | R26: 46119.793 | S26: 0.12143519 | T26: within | V26: 17595652 | W26: Resolved | X26: No Issue found on site visit | Z26: As per our visit regarding the customer’s slow browsing issue, we found that the problem is related to the TV receiver application not working. We advised the customer to contact the TV receiver service provider for further assistance. All network parameters were checked and found to be normal. Speed tests were performed using LAN cable, Wi-Fi 2.4G, and Wi-Fi 5G, and all were working fine. | AC26: Damaged | AJ26: Not required
A27: 46119 | B27: Rajesh | C27: Controller Waqas | D27: 20072427 | E27: ESSENTIAL_300M_60M | F27: BUD | G27: 529 | H27: 45 | I27: 68 | J27: 62 | K27: Los | L27: 39166666 | M27: Appoiment 7/4/2026 @ before 6pm as per cusomer Red Los on ONT | N27: GPON Service Assurance | O27: Batelco | P27: 46119.679 | Q27: 46119.804 | R27: 46119.772 | S27: 0.092662037 | T27: within | V27: WBS_768374_1 | W27: Resolved | X27: Customer Related Issue | Y27: Customer Internal Network Issue | Z27: Visit Report (LOS Issue):-As per our visit for the LOS issue, we found that the customer’s cleaning team had accidentally turned off the ONT. We powered it back on, and the internet service is now restored and working normally. However, the customer is still experiencing an issue with the WiFi access point on the first floor. The customer will coordinate with their IT team to resolve this issue. | AJ27: Not required
A28: 46120 | B28: Mohsin | C28: Controller Aditi | D28: 20072434 | E28: ESSENTIAL_500M_250M | F28: ROW | G28: 1209 | H28: 906 | I28: 349 | J28: 0 | K28: Internet Disconnection on all the devices, " TV, Mobile, and Laptop." Also, he noticed a speed drop to 50 Mbps. | L28: 39690300 | M28: Appointment 08/04/2026@8 to 10 We contacted the customer, and he reported experiencing frequent disconnections and speed issues. The internet connection is unstable across all devices. The customer has requested a team visit to investigate and resolve the issue. Rx Optical Power (dBm) = -13.8 | N28: GPON Service Assurance | O28: STC | P28: 46119.714 | Q28: 46119.714 | R28: 46120.494 | S28: 0.78020833 | T28: within | V28: WBS_341577_1 | W28: Resolved | X28: Customer Related Issue | Y28: Customer internal Network Issue | Z28: On visit as per customer said internal disconnection issue we checked the connection end-to-end and and RX power; everything was found to be normal. During our inspection, we identified that the customer using wifi extenders more then 3 all this not working properly we reconfigure all 3 extenders now line working fine .... | AA28: Non-Genuine Ticket | AB28: 46119.839 | AJ28: Not required
A29: 46120 | B29: Rajesh | C29: Controller Waqas | D29: 20072454 | E29: ESSENTIAL_300M_60M | F29: NZA | G29: 1211 | H29: 1143 | I29: 2616 | J29: 0 | K29: cannot connect with network | L29: 39622291 | M29: Appointment 08/04/2026@9 or after We contacted the customer, and he informed us that he is able to connect to the Wi-Fi; however, there is no internet access. We attempted to resolve the issue by changing the Wi-Fi name and password, but the issue persists. The customer has requested a site visit for further inspection. Rx Optical Power (dBm) = -12.81 | N29: GPON Service Assurance | O29: Batelco | P29: 46119.825 | Q29: 46119.95 | R29: 46120.486 | S29: 0.6609838 | T29: within | U29: Appointment Rescheduled | V29: 17430930 | W29: Resolved | X29: Customer Related Issue | Y29: Customer internal Network Issue | Z29: As per our visit for the disconnection / no browsing issue, we checked the connection end-to-end and verified line stability and RX power; all parameters were within normal range. During our inspection, we found that the customer had connected a LAN cable from the ONT back to the same ONT, creating a loop, which caused the internet service to stop working. We removed the loop connection and corrected the setup. After rectification, the line was restored and internet service is working normally. The issue was explained to the customer. From our side, everything is functioning properly. | AA29: Non-Genuine Ticket | AJ29: Not required
A30: 46120 | B30: Rajesh | C30: Controller Aditi | D30: 20072501 | E30: ESSENTIAL_300M_60M | F30: DUM | G30: 1016 | H30: 1610 | I30: 866 | K30: Not able to connect to PS5 | L30: 39999750 | M30: Appointment 8/4/2026 @ 1pm/ Customer said sometimes working sometime disconnected | N30: GPON Service Assurance | O30: STC | P30: 46120.442 | Q30: 46120.442 | R30: 46120.592 | S30: 0.14953704 | T30: within | V30: WBS_591110_1 | W30: Resolved | X30: Customer Related Issue | Y30: Customer internal Network Issue | Z30: As per our visit for the disconnection issue and PlayStation connectivity issue, we checked the connection from our side and verified line stability. Ping tests were conducted through LAN and WiFi, and no disconnection was detected. We also performed speed tests via LAN and WiFi, and the results were as per the subscribed package. The customer is using network switches for internal connectivity. Upon inspection, no issues were found from the ONT side. The PlayStation is showing some kind of error which is not related to the internet connection. From our side, the connection is working normally | AA30: Non-Genuine Ticket | AB30: 46120.488 | AJ30: Not required
A31: 46120 | B31: Mohsin | C31: Controller Waqas | D31: 20072500 | E31: ESSENTIAL_300M_60M | F31: ROW | G31: 1211 | H31: 1141 | I31: 2532 | K31: no able to connect to PS | L31: 33394304 | M31: Appointment 8/4/2026 @ 4PM. Customer said internet not works with playstation and he need a team to visit him | N31: GPON Service Assurance | O31: STC | P31: 46120.441 | Q31: 46120.441 | R31: 46120.653 | S31: 0.21185185 | T31: within | V31: WBS_623700_1 | W31: Resolved | X31: Customer Related Issue | Y31: Customer internal Network Issue | Z31: As per our site visit regarding the customer’s PlayStation not working, we performed an end-to-end check of the connection, including verification of RX power. All parameters were found to be within the normal range. We advised the customer to follow up with the Service provider for further assistance. Additionally, speed tests were conducted to verify performance, and the results were normal across 2.4 GHz, 5 GHz, and LAN connections. The line is working properly as per the subscribed package. | AA31: Non-Genuine Ticket | AB31: 0.46875 | AJ31: Not required
A32: 46120 | B32: Rajesh | C32: Controller Yasser | D32: 20072497 | E32: ESSENTIAL_500M_250M | F32: BUD | G32: 538 | H32: 3824 | I32: 1011 | K32: TT 1-245836074207 regarding low internet speed. | L32: 33277882 | M32: Repeated SR 20070821 - Appointment 8/4/2026 4 to5pm/ Customer Said as per customer there is some issue in speed | N32: GPON Service Assurance | O32: STC | P32: 46120.438 | Q32: 46120.438 | R32: 46120.743 | S32: 0.30528935 | T32: within | V32: WBS_713730_1 | W32: Resolved | X32: No Issue found on site visit | Z32: As per our visit for the customer’s internet issue, we checked the connection end-to-end and verified line stability and RX power; all parameters were normal. The customer’s main concern is related to PlayStation online gaming. When attempting to sign in for online gaming, the connection fails. However, when the customer connects the PlayStation using a mobile hotspot from another service provider, the online gaming works properly. The customer also confirmed that the service works fine when using a friend’s 5G CPE connection. Based on our checks, no issues were found from the BNET side during testing. | AC32: Damaged | AJ32: Not required
A33: 46120 | B33: Mohsin | C33: Controller Yasser | D33: 20072504 | E33: ESSENTIAL_300M_60M | F33: NZA | G33: 1056 | H33: 5664 | I33: 3665 A | K33: Not able to connect to PS5 | L33: 39925445 | M33: Appointment 8/4/2026 @ Open time/ Call before as per customer he is unable to connect the playstation and asking a team to visit and check | N33: GPON Service Assurance | O33: STC | P33: 46120.447 | Q33: 46120.447 | R33: 46120.792 | S33: 0.34510417 | T33: within | V33: WBS_768237_1 | W33: Resolved | X33: No Issue found on site visit | Z33: As per our visit for the customer’s internet issue, we checked the connection end-to-end and verified line stability and RX power; all parameters were normal. The customer’s main concern is related to PlayStation online gaming. When attempting to sign in for online gaming, the connection fails. And also we connects the PlayStation using a mobile hotspot also same connection fails showing customer also agree... He said he will check PlayStation customer service... ...we also performed speed tests via wifi and Lan cable as per customer package speed working properly | AA33: Non-Genuine Ticket | AB33: 0.51736111 | AC33: Damaged | AJ33: Not required
A34: 46120 | B34: Rajesh | C34: Controller Yasser | D34: 20072518 | E34: ESSENTIAL_300M_60M | F34: BUD | G34: 540 | H34: 4077 | I34: 2223 | K34: Please note that the customer is facing multiple disconnection on his device all the time he needs some one to visit and check his device he think that might he has issue with the device. | L34: 36333838 | M34: App 8 April/Open time. As per customer internet disconnect after 5m from ONT and not working on both need a team to check | N34: GPON Service Assurance | O34: STC | P34: 46120.544 | Q34: 46120.544 | R34: 46120.68 | S34: 0.13619213 | T34: within | V34: WBS_725409_1 | W34: Resolved | X34: No Issue found on site visit | Z34: As per our visit for the disconnection issue, we checked the connection end-to-end and verified line stability and RX power; all parameters were normal. The subscribed speed (100/20 Mbps) was confirmed by the ISP. We conducted ping tests and no disconnection was detected. Speed tests were also performed through both LAN and WiFi, and the results were as per the subscribed package. However, the customer reported experiencing intermittent disconnections since the time of installation and has raised multiple complaints with the ISP. The customer also stated that devices such as TV and mobile phones occasionally face browsing issues. At the time of our visit, no issues were observed from our side. The customer is requesting ONT replacement despite no faults being detected during testing. | AA34: Non-Genuine Ticket | AB34: 13:40:00 PM | AC34: Damaged | AJ34: Not required
A35: 46120 | B35: Bilal | C35: Controller Yasser | D35: 20072517 | E35: ESSENTIAL_300M_60M | F35: ROW | G35: 1034 | H35: 32 | I35: 120 | J35: 13 | K35: The customer cannot use the network, and 5G is not working for them. 4G is very slow, in TR online. TS done from tow days. The customer wants to file a complaint that the service is unsatisfactory and is upset because they have been affected for several days. | L35: 34515151 | M35: App 8 April/Open time. Customer need a team to visit and check as per him internet suddenly stop working | N35: GPON Service Assurance | O35: STC | P35: 46120.544 | Q35: 46120.544 | R35: 46120.737 | S35: 0.19366898 | T35: within | V35: WBS_690650_1 | W35: Resolved | X35: No Issue found on site visit | Z35: Upon inspection, no issues were identified, and the line was found to be working properly. We tested the connection using both LAN cable and Wi-Fi, and both were functioning normally. Additionally, we confirmed with the ISP that the customer’s subscribed package provides 100 Mbps download and 20 Mbps upload speeds. customer have issue from hes PC | AC35: Damaged | AJ35: Not required
A36: 46120 | B36: Rajesh | C36: Controller Yasser | D36: 20072533 | E36: ESSENTIAL_300M_60M | F36: BUD | G36: 575 | H36: 7516 | I36: 945 | J36: 0 | K36: as per our last visit The customer has a problem with their fiber device | L36: 38400100 | M36: Appointment 08/04/2026@ 5 or after We contacted the customer, and he informed us that he is able to connect to the Wi-Fi; however, there is no internet access. We attempted to resolve the issue by changing the Wi-Fi name and password, but the issue persists. The customer has requested a site visit for further inspection. Rx Optical Power (dBm) = -17.28 | N36: GPON Service Assurance | O36: STC | P36: 46120.64 | Q36: 46120.64 | R36: 46120.788 | S36: 0.14853009 | T36: within | V36: WBS_763201_1 | W36: Resolved | X36: No Issue found on site visit | Z36: As per our visit for the disconnection issue, we checked the connection end-to-end and verified line stability and RX power; all parameters were normal. During our inspection, we found that the customer was using a secondary ONT as a WiFi access point, connected to the main ONT. This setup was causing network instability and disconnections. When we removed the LAN cable connected to the secondary ONT, the line became stable and the internet started working properly. The customer was informed that for proper WiFi coverage, they should contact the service provider for a suitable solution (e.g., installation of a proper WiFi access point). From our side, the connection is working normally. | AC36: Damaged | AJ36: Not required
A37: 46120 | B37: Bilal | C37: Controller Yasser | D37: 20072536 | E37: ESSENTIAL_300M_60M | F37: ROW | G37: 1205 | H37: 543 | I37: 2695B | J37: 0 | K37: customer complaining about a dropped speed even if he connects near to the router | L37: 36677164 | M37: Appointment 08/04/2026@Anytime We contacted the customer, and he informed us that he is able to connect to the Wi-Fi; however, there is no internet access. We attempted to resolve the issue by changing the Wi-Fi name and password, but the issue persists. The customer has requested a site visit for further inspection. | N37: GPON Service Assurance | O37: STC | P37: 46120.661 | Q37: 46120.661 | R37: 46120.831 | S37: 0.16989583 | T37: within | V37: WBS_585202_1 | W37: Resolved | X37: No Issue found on site visit | Z37: customer complained about the disconnection during our visit we checked the line end-to-end and found over line is working properly customer have issue from Redbox.. no technical issue found.. | AC37: Damaged | AJ37: Not required
A38: 46120 | B38: Bilal | C38: Controller Yasser | D38: 20072537 | E38: ESSENTIAL_300M_60M | F38: ROW | G38: 1020 | H38: 2027 | I38: 2212 | J38: 73 | K38: Customer is facing disconnection and cannot connect on wifi | L38: 36624431 | M38: Appointment 08/04/2026@Anytime We contacted the customer, and he informed us that he is able to connect to the Wi-Fi; however, there is no internet access. We attempted to resolve the issue by changing the Wi-Fi name and password, but the issue persists. The customer has requested a site visit for further inspection. | N38: GPON Service Assurance | O38: Batelco | P38: 46120.679 | Q38: 46120.804 | R38: 46120.875 | S38: 0.19584491 | T38: within | V38: 21007049 | W38: Resolved | X38: No Issue found on site visit | Z38: The customer reported experiencing disconnection issues. During our visit, we performed a complete end-to-end line check and confirmed that the ONT is working properly. No technical issues were identified from our side. The customer suspects that the issue may be related to weak Wi-Fi signal/coverage. | AC38: Damaged | AJ38: Not required
A39: 46121 | B39: mohsin | C39: Controller Aditi | D39: 20072544 | E39: ESSENTIAL_300M_60M | F39: ROW | G39: 1210 | H39: 1005 | I39: 218 | J39: 0 | K39: customer claiming router have issue kindly she is requesting for replacement | L39: 39454712 | M39: Appointment 09/04/2026@8 to 10 call before visit We contacted the customer, who reported experiencing frequent disconnections with the router even when in close proximity. The customer has requested a site visit for further inspection and resolution. Rx Optical Power (dBm) = -21.25 | N39: GPON Service Assurance | O39: Batelco | P39: 46120.722 | Q39: 46120.847 | R39: 46121.409 | S39: 0.68677083 | T39: within | V39: 17682657 | W39: Resolved | X39: No Issue found on site visit | Y39: No Issue found on site visit | Z39: Customer facing wifi coverage issue his daughter. Room ...on visit we found ont location to Customer room long distance, advice to customer contact service provider for proper WiFi access point installation..... Line is working fine. | AA39: Non-Genuine Ticket | AJ39: Not required
A40: 46121 | B40: Bilal | C40: Controller Waqas | D40: 20072642 | E40: ESSENTIAL_300M_60M | F40: BUD | G40: 514 | H40: 60 | I40: 622 | J40: 0 | K40: customer have old ONT and he get several issues regarding that and the internet not stable .please replace the ONT | L40: 39766693 | M40: Appointment 09/04/2026@5 called customer and customer is facing disconnection in his line she wants a team to check. power is normal | N40: GPON Service Assurance | O40: Batelco | P40: 46121.659 | Q40: 46121.784 | R40: 46121.763 | S40: 0.1033912 | T40: within | V40: 17596693 | W40: Resolved | X40: No Issue found on site visit | Y40: No Issue found on site visit | Z40: Customer complained about disconnection. During our visit, we checked the line end-to-end and found RX power stable within the normal range. Speed tests were performed on both bands, and a ping test was also conducted. No issues were observed. The line is working properly. Note : Customer actual package is 300/60 Confirmed by ISP | AA40: Non-Genuine Ticket | AJ40: Not required
...

Sheet Non-Genuine Ticket Tracker 
A1: Ticket_Number | B1: Date_Ticket_Created | C1: Date_Ticket_Closed | D1: Contractor_Name | E1: Area_Location | F1: LO_Operator | G1: Customer_Name | H1: Customer_Contact | I1: Customer_Contacted | J1: Call_Date | K1: Call_Time | L1: Communication_Method | M1: Troubleshooting_Conducted | N1: Issue_Description | O1: Actions_Taken | P1: Issue_Resolved_On_Call | Q1: Final_Ticket_Status | R1: Visit_Appointment_Date | S1: Customer_Confirmation | T1: Reason_Non_Genuine | U1: Additional_Remarks | V1: Technician_Confirmation | W1: Compliance_Status | X1: BNET_Remarks
A2: 20060977 | B2: 46092 | C2: 46093 | D2: Whitepearls | E2: BUD | F2: STC | G2: - | H2: 38560002 | I2: Yes | J2: 46093 | K2: 0.56180556 | L2: Phone | M2: Yes | N2: Slow Browing | O2: Reconfigured | P2: Yes | Q2: Non-Genuine | R2: - | S2: Yes | T2: No Issue Found Remotely | U2: Add Full Details | V2: No | W2: Will be Filled By BNET | X2: Will be Filled By BNET
A3: 20060766 | B3: 46092 | C3: 46093 | D3: Whitepearls | E3: RIF | F3: Zain | G3: - | H3: 38560002 | I3: Yes | J3: 46093 | K3: 0.57638889 | L3: Phone | M3: Yes | N3: Diconnection | O3: Reconfigured | P3: No | Q3: Converted to Visit | R3: 46093 | S3: Yes | T3: No Issue Found on Visit | U3: Add Full Details | V3: Yes | W3: Will be Filled By BNET | X3: Will be Filled By BNET
W4: Will be Filled By BNET | X4: Will be Filled By BNET
A5: 20069714 | B5: 46089.68 | C5: 46093.379 | D5: Whitepearls | E5: SAR | F5: Zain | G5: - | H5: 39365859 | I5: Yes | J5: 46093 | K5: 0.3665625 | L5: Phone | M5: Yes | N5: Slow Browing | O5: Reconfigured | P5: No | Q5: Converted to Visit | R5: 46093 | S5: Yes | T5: No Issue Found on Visit | U5: As per visit for internet disconnection issue, Bnet and Huawei technical team visited the customer premises. We checked the connection end-to-end and verified the configuration. A continuous ping test was performed for around 1 hour, and no disconnection was observed from our side. However, the customer still confirms that disconnections occur at different times during the day. Therefore, Bnet and Huawei team concluded to transfer the case to the ISP team to test the customer account or recreate a new internet account if required. From our side, the line and configuration are working normally. | V5: Yes | W5: Will be Filled By BNET | X5: Will be Filled By BNET
A6: 20070036 | B6: 46092.812 | C6: 46093.441 | D6: Whitepearls | E6: BUD | F6: Batelco | G6: - | H6: 97339699111 | I6: Yes | J6: 46093 | K6: 0.83375 | L6: Phone | M6: Yes | N6: Slow Browing | O6: Reconfigured | P6: No | Q6: Converted to Visit | R6: 46093 | S6: Yes | T6: ONT Faulty Replaced | U6: Ont replaced Q to F50 due to speed issue as customer package is 1GB which is not support in Q model New 48575443F09AAAB6 Old 485754432986FB9A | V6: Yes | W6: Will be Filled By BNET | X6: Will be Filled By BNET
A7: 20070057 | B7: 46092.996 | C7: 46093.457 | D7: Whitepearls | E7: BUD | F7: Batelco | G7: - | H7: 36660657 | I7: Yes | J7: 46093 | K7: 0.34427083 | L7: Phone | M7: Yes | N7: Diconnection | O7: Reconfigured | P7: No | Q7: Converted to Visit | R7: 46093 | S7: Yes | T7: Replaced Faulty SC/UPC Connector in OH FTB | U7: Blue connector damaged in OTB cause by environmental factors, replaced new | V7: Yes | W7: Will be Filled By BNET | X7: Will be Filled By BNET
A8: 20070054 | B8: 46092.981 | C8: 46093.506 | D8: Whitepearls | E8: NZA | F8: Batelco | G8: - | H8: 33448883 | I8: Yes | J8: 46093 | K8: 0.34645833 | L8: Phone | M8: Yes | N8: Slow Browing | O8: Reconfigured | P8: No | Q8: Converted to Visit | R8: 46093 | S8: Yes | T8: ONT Faulty Replaced | U8: ont faulty due to wifi 2.4G speed not getting as per the plan .... X6 to F50 ont replaced now line working fine New sno:48575443FBC6DBB6 Old sno:4857544352FB30AF | V8: Yes | W8: Will be Filled By BNET | X8: Will be Filled By BNET
A9: 20070049 | B9: 46092.93 | C9: 46093.548 | D9: Whitepearls | E9: ROW | F9: Batelco | G9: - | H9: 39262112 | I9: Yes | J9: 46093 | K9: 0.34847222 | L9: Phone | M9: Yes | N9: Slow Browing | O9: Reconfigured | P9: No | Q9: Converted to Visit | R9: 46093 | S9: Yes | T9: ONT Hard Reset | U9: Customer having problem with coverage issue on visit we found customer having wifi extender not connected to main ont reconfigure SSID onmain ont now customer extender also working fine ...coverage issue resolved...now line working fine | V9: Yes | W9: Will be Filled By BNET | X9: Will be Filled By BNET
A10: 20070045 | B10: 46092.904 | C10: 46093.54 | D10: Whitepearls | E10: BUD | F10: Batelco | G10: - | H10: 39754475 | I10: Yes | J10: 46093 | K10: 0.35708333 | L10: Phone | M10: Yes | N10: country region issue | O10: Reconfigured | P10: No | Q10: Converted to Visit | R10: 46093 | S10: Yes | T10: ONT Hard Reset | U10: As per visit, ONT was hard reset and reconfigured due to WiFi 5G not showing. After reconfiguration, the service has been restored and both WiFi bands are working normally. Line is stable and everything is working fine now. | V10: Yes | W10: Will be Filled By BNET | X10: Will be Filled By BNET
A11: 20070067 | B11: 46093.419 | C11: 46093.512 | D11: Whitepearls | E11: MSH | F11: Batelco | G11: - | H11: 97339092826 | I11: Yes | J11: 46093 | K11: 0.43319444 | L11: Phone | M11: Yes | N11: Slow Browing | O11: Reconfigured | P11: No | Q11: Converted to Visit | R11: 46093 | S11: Yes | T11: Patch Cord Damaged - Replaced | U11: As per our visit for the disconnection issue, we checked the connection end-to-end and found that the patch cord inside the table area was slightly bent by the customer. We replaced it with a new patch cord. After replacement, we checked the connection through ping test and performed speed tests via both Wi-Fi and LAN. Everything is working fine and stable from our side. | V11: Yes | W11: Will be Filled By BNET | X11: Will be Filled By BNET
A12: 20070082 | B12: 46093.536 | C12: 46093.616 | D12: Whitepearls | E12: HAM | F12: Batelco | G12: - | H12: 38888813 | I12: Yes | J12: 46093 | K12: 0.54738426 | L12: Phone | M12: Yes | N12: Slow Browing | O12: Reconfigured | P12: No | Q12: Converted to Visit | R12: 46093 | S12: Yes | T12: SC/UPC Blue Connector Damaged in Internal FTB - Replaced | U12: Semplex damaged by customer we replaced semplex now line working fine | V12: Yes | W12: Will be Filled By BNET | X12: Will be Filled By BNET
A13: 20070197 | B13: 46095.227 | C13: 46095.771 | D13: Whitepearls | E13: AWA | F13: Batelco | G13: - | H13: 66666947 38322003 | I13: Yes | J13: 46095 | K13: 0.60902778 | L13: Phone | M13: Yes | N13: Diconnection | O13: Reconfigured | P13: No | Q13: Converted to Visit | R13: 46095 | S13: Yes | T13: No Issue Found on Visit | U13: No issue found on site visit - customer was unable to connect to 5g, on visit no issue found by team - after restart issue resolved for customer aswell. | V13: Yes | W13: Will be Filled By BNET | X13: Will be Filled By BNET
A14: 20070137 | B14: 46094.249 | C14: 46095.497 | D14: Whitepearls | E14: BUD | F14: Batelco | H14: 32121661 | I14: Yes | J14: 46094 | K14: 0.6637037 | L14: Phone | M14: Yes | N14: Slow Browing | O14: Reconfigured | P14: No | Q14: Converted to Visit | R14: 46095 | S14: Yes | T14: Customer related issue | U14: customer complaining about of the disconnection we checked end to end ont working properly maybe customer have issue from hes TV . over ont working fine.. | V14: Yes | W14: Will be Filled By BNET | X14: Will be Filled By BNET
A15: 20070179 | B15: 46094.917 | C15: 46095.671 | D15: Whitepearls | E15: JZR | F15: Batelco | H15: 39323113 | I15: Yes | J15: 46095 | K15: 0.53233796 | L15: Phone | M15: Yes | N15: Diconnection | O15: Reconfigured | P15: No | Q15: Converted to Visit | R15: 46095 | S15: Yes | T15: No Issue found on site visit | U15: As per our visit for the internet disconnection issue, we checked the connection end-to-end and verified the ONT. We performed multiple ping tests and checked line stability, and everything was found normal. No issue was detected from the ONT side. The customer mentioned that they sometimes experience disconnections. There are several internal devices connected to the ONT, such as CCTV equipment, which may affect the connection. From our side, the internet connection is working normally and no fault was found. | V15: Yes | W15: Will be Filled By BNET | X15: Will be Filled By BNET
A16: 20070139 | B16: 46094.45 | C16: 46095.48 | D16: Whitepearls | E16: SAR | F16: Batelco | H16: 34043143 | I16: Yes | J16: 46094 | K16: 0.66141204 | L16: Phone | M16: Yes | N16: LOS | O16: Reconfigured | P16: No | Q16: Converted to Visit | R16: 46095 | S16: Yes | T16: GPON_Optical_Network_Terminal_ONT | U16: Ont faulty not working at all replaced x6 to F50 New SN:48575443F099FEB6 Old SN:48575443205E21B3 | V16: Yes | W16: Will be Filled By BNET | X16: Will be Filled By BNET
A17: 20070219 | B17: 46095.547 | C17: 46095.571 | D17: Whitepearls | E17: HAM | F17: Batelco | H17: 39296405 | I17: Yes | J17: 46095 | K17: 0.56600694 | L17: Phone | M17: Yes | N17: LOS | O17: Reconfigured | P17: Yes | Q17: Non-Genuine | S17: Yes | T17: No Issue Found Remotely | U17: Profile Reconfigured - Hard Reset | V17: No | W17: Will be Filled By BNET | X17: Will be Filled By BNET
A18: 20069043 | B18: 46081.835 | C18: 46084.744 | D18: Whitepearls | E18: AAL | F18: Batelco | G18: - | H18: 33005352 | I18: Yes | J18: 46082 | K18: 0.60302083 | L18: Phone | M18: Yes | N18: The customer is experiencing internet outages for periods of time. | O18: Reconfigured | P18: No | Q18: Converted to Visit | R18: 46083 | S18: Yes | T18: No Issue found on site visit | U18: during over visit no technical issue found ont working properly. | V18: Yes | W18: Will be Filled By BNET | X18: Will be Filled By BNET
A19: 20069166 | B19: 46083.49 | C19: 46084.792 | D19: Whitepearls | E19: SAR | F19: Kalam | G19: - | H19: 33043523 | I19: Yes | J19: 46083 | K19: 0.62381944 | L19: Phone | M19: Yes | N19: we are not able to ping to the router through our TR069 system | O19: Reconfigured | P19: No | Q19: Converted to Visit | R19: 46083 | S19: Yes | T19: No Issue found on site visit | U19: As our visit we didn't found any issue from ont side, Internet is working fine, as customer facing issue with their internal connectivity not working from ont, our side line rx and speed tests all are fin | V19: Yes | W19: Will be Filled By BNET | X19: Will be Filled By BNET
A20: 20069230 | B20: 46083.942 | C20: 46084.845 | D20: Whitepearls | E20: NZA | F20: Batelco | G20: - | H20: 33448883 | I20: Yes | J20: 46084 | K20: 0.43677083 | L20: Phone | M20: Yes | N20: RX power-11 dBm | O20: Reconfigured | P20: No | Q20: Converted to Visit | R20: 46084 | S20: Yes | T20: No Issue found on site visit | U20: during the visit no technical issue found ont working properly | V20: Yes | W20: Will be Filled By BNET | X20: Will be Filled By BNET
A21: 20069273 | B21: 46084.737 | C21: 46084.726 | D21: Whitepearls | E21: ROW | F21: Batelco | G21: - | H21: 66339377 | I21: Yes | J21: 46084 | K21: 0.65831019 | L21: Phone | M21: Yes | N21: LOS - As per customer the internet keep on disconnecting the internet not stable and need checking by the bnet staff as per customer please check and take needed action customer prefers visit to his house to further investigate the root of the issue | O21: Reconfigured | P21: No | Q21: Converted to Visit | R21: 46085 | S21: Yes | T21: No Issue found on site visit | U21: During the visit the customer have ports switch and the switch was faulty. When the switch was connected with the ONT the ping became high. When it was removed the ONT started working normally. We removed the customer switch and connected the extended cable directly. After this the internet disconnection issue was resolved. | V21: Yes | W21: Will be Filled By BNET | X21: Will be Filled By BNET
A22: 20069106 | B22: 46082.782 | C22: 46088.485 | D22: Whitepearls | E22: ROW | F22: Batelco | G22: - | H22: 38383848 | I22: Yes | J22: 46082 | K22: 0.66795139 | L22: Phone | M22: Yes | N22: LOS | O22: Reconfigured | P22: No | Q22: Converted to Visit | R22: 46083 | S22: Yes | T22: No Issue found on site visit | U22: during the visit no technical issue was found ont working properly but customer said there is coming disconnection and customer is requsting to keep open the ticket -Line is under minitoring | V22: Yes | W22: Will be Filled By BNET | X22: Will be Filled By BNET
A23: 20069506 | B23: 46086.646 | C23: 46088.814 | D23: Whitepearls | E23: ROW | F23: Batelco | G23: - | H23: 38040007/33933043 | I23: Yes | J23: 46086 | K23: 0.68891204 | L23: Phone | M23: Yes | N23: customer said there is noisy sound inside the router | O23: Reconfigured | P23: No | Q23: Converted to Visit | R23: 46088 | S23: Yes | T23: No Issue found on site visit | U23: As per our visit to the customer premises regarding the complaint of a noisy sound from the ONT, we checked the connection end-to-end. After inspection, we confirmed that the noise is not coming from the ONT. The sound is coming from a TV receiver placed near the ONT which has an issue. We informed the customer and confirmed that the ONT is working properly. Internet speed was tested on both 2.4G and 5G WiFi, and everything is working fine as per the package. | V23: Yes | W23: Will be Filled By BNET | X23: Will be Filled By BNET
A24: 20069599 | B24: 46088.641 | C24: 46088.674 | D24: Whitepearls | E24: ROW | F24: Batelco | G24: - | H24: 39083308 | I24: Yes | J24: 46088 | K24: 0.5916088 | L24: Phone | M24: Yes | N24: Customer facing disconnection in internet please check the issue | O24: Reconfigured | P24: No | Q24: Converted to Visit | R24: 46088 | S24: Yes | T24: No Issue found on site visit | U24: During the visit no technical issue was found. The ONT is working normally. The customer has a Redbox installed upstairs which is quite far from the ONT and is connected through Wi-Fi. Due to this the customer is facing disconnection issues. The customer needs the Redbox to be connected with a proper Ethernet cable instead of Wi-Fi. | V24: Yes | W24: Will be Filled By BNET | X24: Will be Filled By BNET
